Workbook

Sheet README
A1: GameData 저작 스프레드시트
A3: 목적 | B3: 이 파일이 콘텐츠(정의) 데이터의 저작 원본. 변환 스크립트가 시트를 읽어 StreamingAssets/Data/*.json 생성(후속 제작).
A5: [공통 규칙]
A6: 1행 = JSON 필드명 | B6: 변환기가 그대로 키로 사용. 수정 금지.
A7: 2행 = 설명 | B7: 사람용 안내. 변환기는 무시.
A8: 3행부터 데이터 | B8: 회색 행은 예시 — 실데이터로 교체할 것.
A9: ID 규칙 | B9: 타입별로 유니크하면 됨(타입 다르면 중복 허용). 대역은 10만 단위: Fish 1xxxxx / Equipment 2xxxxx / Materials 3xxxxx / Consumables 4xxxxx / BattleFish 5xxxxx / Stage 6xxxxx / License 7xxxxx (예: 100001)
A10: 참조(_id 접미) | B10: 다른 시트의 m_id를 적는다. 대상 타입은 열 설명 참조. 빈칸 = null.
A11: 불리언 | B11: TRUE / FALSE
A12: 서브시트 첫 열 = row_key (중복 금지) | B12: 외부 변환 툴이 '첫 열 값'을 JSON 키로 쓰므로 중복되면 행이 소실됨. 서브시트(EquipmentUpgrades/StageTierPools)는 첫 열을 고유 row_key(예: 2001_1)로 쓰고, 부모 id는 둘째 열(equipment_id/stage_id)에 적는다. row_key 값 자체는 로더가 무시.
A13: # 접두 열 = 표시 전용 (JSON 변환 제외) | B13: 헤더가 #로 시작하는 열은 사람용 표시(참조 이름 VLOOKUP·메모 등)이며 내장 변환기가 무시한다. 외부 툴(방법1)로 변환하면 JSON에 포함되지만 로더가 무시하므로 동작엔 영향 없음. 이름 열은 자동 수식이므로 직접 입력하지 말 것.
A14: m_assetKey (에셋 키 규약, D18) | B14: 비주얼 에셋(아이콘·모델)은 Addressables 주소 {클래스명}_{ID}_{용도}로 연결됨 (예: ItemData_Fish_100001_Icon). m_assetKey가 빈칸이면 이 규약 사용. 에셋을 공유(여러 항목이 같은 아이콘)하거나 예외일 때만 m_assetKey에 키 베이스를 입력 (예: Material_CommonFishMeat → 최종 키 Material_CommonFishMeat_Icon). 용도 접미: Icon(UI 아이콘) / Model(월드 프리팹) / Background(스테이지 배경).
A16: [압축 문자열 형식] 항목 구분 ';' 필드 구분 ':'
A17: modifiers | B17: Stat:Op:Value;... 예) DamagePerClick:Add:5;CriticalChance:Add:0.05 (Stat/Op 유효값은 Enums 시트)
A18: materialCosts / craftMaterials | B18: materialId:count;... 예) 3001:2;3002:1
A19: bossDrops | B19: 타입:id:count:확률;... 예) ItemData_Materials:3001:5:0.5;ItemData_Equipment:2001:1:0.1 (확률 0~1)
A20: qualityThresholds | B20: 경계값 4개 오름차순 v1;v2;v3;v4 size<v1→1성 … size>=v4→5성
A21: entries (티어풀) | B21: battleFishId:weight;... 예) 5001:70;5002:5
A23: [시트 → JSON 매핑]
A24: 타입 시트(ItemData_Fish 등) | B24: 행 1개 = JSON 항목 1개 (type은 시트명으로 변환기가 부여)
A25: EquipmentUpgrades | B25: equipment_id별 level 순으로 묶여 해당 장비의 m_upgradeSteps 배열이 됨. 첫 열은 row_key(고유) — 부모 id 아님 주의
A26: StageTierPools | B26: stage_id별로 묶여 해당 스테이지의 m_tierPools 배열이 됨. 첫 열은 row_key(고유) — 부모 id 아님 주의
A27: Enums | B27: 유효값 참조표 — 변환 대상 아님

Sheet Enums
A1: PlayerStat | B1: ModifierOperation | C1: ItemRarity | D1: EquipmentMountingArea | E1: ItemType
A2: DamagePerClick | B2: Add | C2: Normal | D2: FishingRod | E2: Fish
A3: ManualDamagePerHitMultiply | B3: Multiply | C3: Uncommon | D3: FishingLine | E3: Materials
A4: BattleTimeVariable | C4: Rare | D4: Reel | E4: Consumables
A5: CriticalChance | C5: Epic | D5: Lure | E5: Equipment
A6: CriticalMultiply | C6: Legendary | D6: Hat
A7: AutoBattleCooltime | D7: Uniform
A8: AutoSpeedPerTime | D8: Gloves
A9: AutoDamagePerHitMultiply | D9: Engine
A10: MapMovementSpeedPerTime | D10: Storage
A11: InventorySize | D11: GPS
A12: ProbabilityAtFishSize | D12: Bait
A13: ProbabilityAtFishRarity | D13: Groundbait
A14: GoldGettingMultiply

Sheet ItemData_Fish
A1: m_id | B1: m_name | C1: m_type | D1: m_tier | E1: m_basePrice | F1: m_rarity | G1: m_aquariumMaterial_id | H1: #aquariumMaterial_name | I1: m_aquariumProduceTime | J1: m_aquariumDecreaseCount | K1: m_assetKey
A2: 고유 ID (int) | B2: 이름 | C2: Fish 고정 | D2: 티어 (int) | E2: 기준 판매가 (0=판매불가) | F2: 등급 — 종별 고정 (Enums) | G2: 수족관 생산 재료 (ItemData_Materials m_id, 빈칸=없음) | H2: 표시 전용(#) — JSON 변환 제외. 자동(VLOOKUP), 입력 금지 | I2: 기본 생산 주기(초) | J2: 성급당 주기 감소량 | K2: 에셋 키 오버라이드 — 빈칸=규약({클래스명}_{ID}). 여러 항목이 에셋을 공유하거나 스킨/예외일 때만 입력
A3: 100001 | B3: 고등어 | C3: Fish | D3: 1 | E3: 100 | F3: Normal | G3: 300001 | H3: =IFERROR(VLOOKUP(G3,ItemData_Materials!$A:$B,2,FALSE),"") | I3: 60 | J3: 5
A4: 100002 | B4: 참돔 | C4: Fish | D4: 1 | E4: 300 | F4: Rare | G4: 300002 | H4: =IFERROR(VLOOKUP(G4,ItemData_Materials!$A:$B,2,FALSE),"") | I4: 90 | J4: 8
H5: =IFERROR(VLOOKUP(G5,ItemData_Materials!$A:$B,2,FALSE),"")
H6: =IFERROR(VLOOKUP(G6,ItemData_Materials!$A:$B,2,FALSE),"")
H7: =IFERROR(VLOOKUP(G7,ItemData_Materials!$A:$B,2,FALSE),"")
H8: =IFERROR(VLOOKUP(G8,ItemData_Materials!$A:$B,2,FALSE),"")
H9: =IFERROR(VLOOKUP(G9,ItemData_Materials!$A:$B,2,FALSE),"")
H10: =IFERROR(VLOOKUP(G10,ItemData_Materials!$A:$B,2,FALSE),"")
H11: =IFERROR(VLOOKUP(G11,ItemData_Materials!$A:$B,2,FALSE),"")
H12: =IFERROR(VLOOKUP(G12,ItemData_Materials!$A:$B,2,FALSE),"")
H13: =IFERROR(VLOOKUP(G13,ItemData_Materials!$A:$B,2,FALSE),"")
H14: =IFERROR(VLOOKUP(G14,ItemData_Materials!$A:$B,2,FALSE),"")
H15: =IFERROR(VLOOKUP(G15,ItemData_Materials!$A:$B,2,FALSE),"")
H16: =IFERROR(VLOOKUP(G16,ItemData_Materials!$A:$B,2,FALSE),"")
... H300: =IFERROR(VLOOKUP(G300,ItemData_Materials!$A:$B,2,FALSE),"")

Sheet ItemData_Materials
A1: m_id | B1: m_name | C1: m_type | D1: m_tier | E1: m_basePrice | F1: m_assetKey
A2: 고유 ID (int) | B2: 이름 | C2: Materials 고정 | D2: 티어 (int) | E2: 기준 판매가 | F2: 에셋 키 오버라이드 — 빈칸=규약({클래스명}_{ID}). 여러 항목이 에셋을 공유하거나 스킨/예외일 때만 입력
A3: 300001 | B3: 멸치살 | C3: Materials | D3: 1 | E3: 10
A4: 300002 | B4: 새우살 | C4: Materials | D4: 1 | E4: 20

Sheet ItemData_Equipment
A1: m_id | B1: m_name | C1: m_type | D1: m_tier | E1: m_basePrice | F1: m_mountingArea | G1: m_baseModifiers | H1: m_assetKey
A2: 고유 ID (int) | B2: 이름 | C2: Equipment 고정 | D2: 티어 (int) | E2: 기준 판매가 | F2: 부위 (Enums) | G2: 0강 효과 — 압축: Stat:Op:Value;... | H2: 에셋 키 오버라이드 — 빈칸=규약({클래스명}_{ID}). 여러 항목이 에셋을 공유하거나 스킨/예외일 때만 입력
A3: 200001 | B3: 낡은 낚싯대 | C3: Equipment | D3: 1 | E3: 50 | F3: FishingRod | G3: DamagePerClick:Add:5
A4: 200002 | B4: 낡은 릴 | C4: Equipment | D4: 1 | E4: 50 | F4: Reel | G4: CriticalChance:Add:0.05

Sheet EquipmentUpgrades
A1: row_key | B1: equipment_id | C1: #equipment_name | D1: level | E1: m_goldCost | F1: m_modifiers | G1: m_materialCosts | H1: #materialCosts_name
A2: 고유 행 키 (예: 부모id_순번). 변환기는 값 자체를 무시 — 중복만 금지 | B2: 대상 장비 (ItemData_Equipment m_id) | C2: 표시 전용(#) — JSON 변환 제외. 자동(VLOOKUP), 입력 금지 | D2: 강화 단계 (1~10) | E2: 이 단계로 올리는 골드 | F2: 이 단계 도달 시 효과(누적치) — 압축 | G2: 재료 비용 — 압축: materialId:count;... | H2: 표시 전용(#) — 압축 문자열 이름 해석(최대 5항목). 자동, 입력 금지
A3: 200001_1 | B3: 200001 | C3: =IFERROR(VLOOKUP(B3,ItemData_Equipment!$A:$B,2,FALSE),"") | D3: 1 | E3: 100 | F3: DamagePerClick:Add:8 | G3: 300001:2 | H3: =IF(G3="","",TEXTJOIN("; ",TRUE,IF(TRIM(MID(SUBSTITUTE(G3,";",REPT(" ",99)),1,99))="","",IFERROR(VLOOKUP(--LEFT(TRIM(MID(SUBSTITUTE(G3,";",REPT(" ",99)),1,99)),FIND(":",TRIM(MID(SUBSTITUTE(G3,";",REPT(" ",99)),1,99)))-1),_Lookup!$A:$B,2,FALSE),"?")&"×"&MID(TRIM(MID(SUBSTITUTE(G3,";",REPT(" ",99)),1,99)),FIND(":",TRIM(MID(SUBSTITUTE(G3,";",REPT(" ",99)),1,99)))+1,99)),IF(TRIM(MID(SUBSTITUTE(G3,";",REPT(" ",99)),100,99))="","",IFERROR(VLOOKUP(--LEFT(TRIM(MID(SUBSTITUTE(G3,";",REPT(" ",99)),100,99)),FIND(":",TRIM(MID(SUBSTITUTE(G3,";",REPT(" ",99)),100,99)))-1),_Lookup!$A:$B,2,FALSE),"?")&"×"&MID(TRIM(MID(SUBSTITUTE(G3,";",REPT(" ",99)),100,99)),FIND(":",TRIM(MID(SUBSTITUTE(G3,";",REPT(" ",99)),100,99)))+1,99)),IF(TRIM(MID(SUBSTITUTE(G3,";",REPT(" ",99)),199,99))="","",IFERROR(VLOOKUP(--LEFT(TRIM(MID(SUBSTITUTE(G3,";",REPT(" ",99)),199,99)),FIND(":",TRIM(MID(SUBSTITUTE(G3,";",REPT(" ",99)),199,99)))-1),_Lookup!$A:$B,2,FALSE),"?")&"×"&MID(TRIM(MID(SUBSTITUTE(G3,";",REPT(" ",99)),199,99)),FIND(":",TRIM(MID(SUBSTITUTE(G3,";",REPT(" ",99)),199,99)))+1,99)),IF(TRIM(MID(SUBSTITUTE(G3,";",REPT(" ",99)),298,99))="","",IFERROR(VLOOKUP(--LEFT(TRIM(MID(SUBSTITUTE(G3,";",REPT(" ",99)),298,99)),FIND(":",TRIM(MID(SUBSTITUTE(G3,";",REPT(" ",99)),298,99)))-1),_Lookup!$A:$B,2,FALSE),"?")&"×"&MID(TRIM(MID(SUBSTITUTE(G3,";",REPT(" ",99)),298,99)),FIND(":",TRIM(MID(SUBSTITUTE(G3,";",REPT(" ",99)),298,99)))+1,99)),IF(TRIM(MID(SUBSTITUTE(G3,";",REPT(" ",99)),397,99))="","",IFERROR(VLOOKUP(--LEFT(TRIM(MID(SUBSTITUTE(G3,";",REPT(" ",99)),397,99)),FIND(":",TRIM(MID(SUBSTITUTE(G3,";",REPT(" ",99)),397,99)))-1),_Lookup!$A:$B,2,FALSE),"?")&"×"&MID(TRIM(MID(SUBSTITUTE(G3,";",REPT(" ",99)),397,99)),FIND(":",TRIM(MID(SUBSTITUTE(G3,";",REPT(" ",99)),397,99)))+1,99))))
A4: 200001_2 | B4: 200001 | C4: =IFERROR(VLOOKUP(B4,ItemData_Equipment!$A:$B,2,FALSE),"") | D4: 2 | E4: 250 | F4: DamagePerClick:Add:12 | G4: 300001:4 | H4: =IF(G4="","",TEXTJOIN("; ",TRUE,IF(TRIM(MID(SUBSTITUTE(G4,";",REPT(" ",99)),1,99))="","",IFERROR(VLOOKUP(--LEFT(TRIM(MID(SUBSTITUTE(G4,";",REPT(" ",99)),1,99)),FIND(":",TRIM(MID(SUBSTITUTE(G4,";",REPT(" ",99)),1,99)))-1),_Lookup!$A:$B,2,FALSE),"?")&"×"&MID(TRIM(MID(SUBSTITUTE(G4,";",REPT(" ",99)),1,99)),FIND(":",TRIM(MID(SUBSTITUTE(G4,";",REPT(" ",99)),1,99)))+1,99)),IF(TRIM(MID(SUBSTITUTE(G4,";",REPT(" ",99)),100,99))="","",IFERROR(VLOOKUP(--LEFT(TRIM(MID(SUBSTITUTE(G4,";",REPT(" ",99)),100,99)),FIND(":",TRIM(MID(SUBSTITUTE(G4,";",REPT(" ",99)),100,99)))-1),_Lookup!$A:$B,2,FALSE),"?")&"×"&MID(TRIM(MID(SUBSTITUTE(G4,";",REPT(" ",99)),100,99)),FIND(":",TRIM(MID(SUBSTITUTE(G4,";",REPT(" ",99)),100,99)))+1,99)),IF(TRIM(MID(SUBSTITUTE(G4,";",REPT(" ",99)),199,99))="","",IFERROR(VLOOKUP(--LEFT(TRIM(MID(SUBSTITUTE(G4,";",REPT(" ",99)),199,99)),FIND(":",TRIM(MID(SUBSTITUTE(G4,";",REPT(" ",99)),199,99)))-1),_Lookup!$A:$B,2,FALSE),"?")&"×"&MID(TRIM(MID(SUBSTITUTE(G4,";",REPT(" ",99)),199,99)),FIND(":",TRIM(MID(SUBSTITUTE(G4,";",REPT(" ",99)),199,99)))+1,99)),IF(TRIM(MID(SUBSTITUTE(G4,";",REPT(" ",99)),298,99))="","",IFERROR(VLOOKUP(--LEFT(TRIM(MID(SUBSTITUTE(G4,";",REPT(" ",99)),298,99)),FIND(":",TRIM(MID(SUBSTITUTE(G4,";",REPT(" ",99)),298,99)))-1),_Lookup!$A:$B,2,FALSE),"?")&"×"&MID(TRIM(MID(SUBSTITUTE(G4,";",REPT(" ",99)),298,99)),FIND(":",TRIM(MID(SUBSTITUTE(G4,";",REPT(" ",99)),298,99)))+1,99)),IF(TRIM(MID(SUBSTITUTE(G4,";",REPT(" ",99)),397,99))="","",IFERROR(VLOOKUP(--LEFT(TRIM(MID(SUBSTITUTE(G4,";",REPT(" ",99)),397,99)),FIND(":",TRIM(MID(SUBSTITUTE(G4,";",REPT(" ",99)),397,99)))-1),_Lookup!$A:$B,2,FALSE),"?")&"×"&MID(TRIM(MID(SUBSTITUTE(G4,";",REPT(" ",99)),397,99)),FIND(":",TRIM(MID(SUBSTITUTE(G4,";",REPT(" ",99)),397,99)))+1,99))))
A5: 200001_3 | B5: 200001 | C5: =IFERROR(VLOOKUP(B5,ItemData_Equipment!$A:$B,2,FALSE),"") | D5: 3 | E5: 500 | F5: DamagePerClick:Add:18 | G5: 300001:6;300002:2 | H5: =IF(G5="","",TEXTJOIN("; ",TRUE,IF(TRIM(MID(SUBSTITUTE(G5,";",REPT(" ",99)),1,99))="","",IFERROR(VLOOKUP(--LEFT(TRIM(MID(SUBSTITUTE(G5,";",REPT(" ",99)),1,99)),FIND(":",TRIM(MID(SUBSTITUTE(G5,";",REPT(" ",99)),1,99)))-1),_Lookup!$A:$B,2,FALSE),"?")&"×"&MID(TRIM(MID(SUBSTITUTE(G5,";",REPT(" ",99)),1,99)),FIND(":",TRIM(MID(SUBSTITUTE(G5,";",REPT(" ",99)),1,99)))+1,99)),IF(TRIM(MID(SUBSTITUTE(G5,";",REPT(" ",99)),100,99))="","",IFERROR(VLOOKUP(--LEFT(TRIM(MID(SUBSTITUTE(G5,";",REPT(" ",99)),100,99)),FIND(":",TRIM(MID(SUBSTITUTE(G5,";",REPT(" ",99)),100,99)))-1),_Lookup!$A:$B,2,FALSE),"?")&"×"&MID(TRIM(MID(SUBSTITUTE(G5,";",REPT(" ",99)),100,99)),FIND(":",TRIM(MID(SUBSTITUTE(G5,";",REPT(" ",99)),100,99)))+1,99)),IF(TRIM(MID(SUBSTITUTE(G5,";",REPT(" ",99)),199,99))="","",IFERROR(VLOOKUP(--LEFT(TRIM(MID(SUBSTITUTE(G5,";",REPT(" ",99)),199,99)),FIND(":",TRIM(MID(SUBSTITUTE(G5,";",REPT(" ",99)),199,99)))-1),_Lookup!$A:$B,2,FALSE),"?")&"×"&MID(TRIM(MID(SUBSTITUTE(G5,";",REPT(" ",99)),199,99)),FIND(":",TRIM(MID(SUBSTITUTE(G5,";",REPT(" ",99)),199,99)))+1,99)),IF(TRIM(MID(SUBSTITUTE(G5,";",REPT(" ",99)),298,99))="","",IFERROR(VLOOKUP(--LEFT(TRIM(MID(SUBSTITUTE(G5,";",REPT(" ",99)),298,99)),FIND(":",TRIM(MID(SUBSTITUTE(G5,";",REPT(" ",99)),298,99)))-1),_Lookup!$A:$B,2,FALSE),"?")&"×"&MID(TRIM(MID(SUBSTITUTE(G5,";",REPT(" ",99)),298,99)),FIND(":",TRIM(MID(SUBSTITUTE(G5,";",REPT(" ",99)),298,99)))+1,99)),IF(TRIM(MID(SUBSTITUTE(G5,";",REPT(" ",99)),397,99))="","",IFERROR(VLOOKUP(--LEFT(TRIM(MID(SUBSTITUTE(G5,";",REPT(" ",99)),397,99)),FIND(":",TRIM(MID(SUBSTITUTE(G5,";",REPT(" ",99)),397,99)))-1),_Lookup!$A:$B,2,FALSE),"?")&"×"&MID(TRIM(MID(SUBSTITUTE(G5,";",REPT(" ",99)),397,99)),FIND(":",TRIM(MID(SUBSTITUTE(G5,";",REPT(" ",99)),397,99)))+1,99))))
C6: =IFERROR(VLOOKUP(B6,ItemData_Equipment!$A:$B,2,FALSE),"") | H6: =IF(G6="","",TEXTJOIN("; ",TRUE,IF(TRIM(MID(SUBSTITUTE(G6,";",REPT(" ",99)),1,99))="","",IFERROR(VLOOKUP(--LEFT(TRIM(MID(SUBSTITUTE(G6,";",REPT(" ",99)),1,99)),FIND(":",TRIM(MID(SUBSTITUTE(G6,";",REPT(" ",99)),1,99)))-1),_Lookup!$A:$B,2,FALSE),"?")&"×"&MID(TRIM(MID(SUBSTITUTE(G6,";",REPT(" ",99)),1,99)),FIND(":",TRIM(MID(SUBSTITUTE(G6,";",REPT(" ",99)),1,99)))+1,99)),IF(TRIM(MID(SUBSTITUTE(G6,";",REPT(" ",99)),100,99))="","",IFERROR(VLOOKUP(--LEFT(TRIM(MID(SUBSTITUTE(G6,";",REPT(" ",99)),100,99)),FIND(":",TRIM(MID(SUBSTITUTE(G6,";",REPT(" ",99)),100,99)))-1),_Lookup!$A:$B,2,FALSE),"?")&"×"&MID(TRIM(MID(SUBSTITUTE(G6,";",REPT(" ",99)),100,99)),FIND(":",TRIM(MID(SUBSTITUTE(G6,";",REPT(" ",99)),100,99)))+1,99)),IF(TRIM(MID(SUBSTITUTE(G6,";",REPT(" ",99)),199,99))="","",IFERROR(VLOOKUP(--LEFT(TRIM(MID(SUBSTITUTE(G6,";",REPT(" ",99)),199,99)),FIND(":",TRIM(MID(SUBSTITUTE(G6,";",REPT(" ",99)),199,99)))-1),_Lookup!$A:$B,2,FALSE),"?")&"×"&MID(TRIM(MID(SUBSTITUTE(G6,";",REPT(" ",99)),199,99)),FIND(":",TRIM(MID(SUBSTITUTE(G6,";",REPT(" ",99)),199,99)))+1,99)),IF(TRIM(MID(SUBSTITUTE(G6,";",REPT(" ",99)),298,99))="","",IFERROR(VLOOKUP(--LEFT(TRIM(MID(SUBSTITUTE(G6,";",REPT(" ",99)),298,99)),FIND(":",TRIM(MID(SUBSTITUTE(G6,";",REPT(" ",99)),298,99)))-1),_Lookup!$A:$B,2,FALSE),"?")&"×"&MID(TRIM(MID(SUBSTITUTE(G6,";",REPT(" ",99)),298,99)),FIND(":",TRIM(MID(SUBSTITUTE(G6,";",REPT(" ",99)),298,99)))+1,99)),IF(TRIM(MID(SUBSTITUTE(G6,";",REPT(" ",99)),397,99))="","",IFERROR(VLOOKUP(--LEFT(TRIM(MID(SUBSTITUTE(G6,";",REPT(" ",99)),397,99)),FIND(":",TRIM(MID(SUBSTITUTE(G6,";",REPT(" ",99)),397,99)))-1),_Lookup!$A:$B,2,FALSE),"?")&"×"&MID(TRIM(MID(SUBSTITUTE(G6,";",REPT(" ",99)),397,99)),FIND(":",TRIM(MID(SUBSTITUTE(G6,";",REPT(" ",99)),397,99)))+1,99))))
C7: =IFERROR(VLOOKUP(B7,ItemData_Equipment!$A:$B,2,FALSE),"") | H7: =IF(G7="","",TEXTJOIN("; ",TRUE,IF(TRIM(MID(SUBSTITUTE(G7,";",REPT(" ",99)),1,99))="","",IFERROR(VLOOKUP(--LEFT(TRIM(MID(SUBSTITUTE(G7,";",REPT(" ",99)),1,99)),FIND(":",TRIM(MID(SUBSTITUTE(G7,";",REPT(" ",99)),1,99)))-1),_Lookup!$A:$B,2,FALSE),"?")&"×"&MID(TRIM(MID(SUBSTITUTE(G7,";",REPT(" ",99)),1,99)),FIND(":",TRIM(MID(SUBSTITUTE(G7,";",REPT(" ",99)),1,99)))+1,99)),IF(TRIM(MID(SUBSTITUTE(G7,";",REPT(" ",99)),100,99))="","",IFERROR(VLOOKUP(--LEFT(TRIM(MID(SUBSTITUTE(G7,";",REPT(" ",99)),100,99)),FIND(":",TRIM(MID(SUBSTITUTE(G7,";",REPT(" ",99)),100,99)))-1),_Lookup!$A:$B,2,FALSE),"?")&"×"&MID(TRIM(MID(SUBSTITUTE(G7,";",REPT(" ",99)),100,99)),FIND(":",TRIM(MID(SUBSTITUTE(G7,";",REPT(" ",99)),100,99)))+1,99)),IF(TRIM(MID(SUBSTITUTE(G7,";",REPT(" ",99)),199,99))="","",IFERROR(VLOOKUP(--LEFT(TRIM(MID(SUBSTITUTE(G7,";",REPT(" ",99)),199,99)),FIND(":",TRIM(MID(SUBSTITUTE(G7,";",REPT(" ",99)),199,99)))-1),_Lookup!$A:$B,2,FALSE),"?")&"×"&MID(TRIM(MID(SUBSTITUTE(G7,";",REPT(" ",99)),199,99)),FIND(":",TRIM(MID(SUBSTITUTE(G7,";",REPT(" ",99)),199,99)))+1,99)),IF(TRIM(MID(SUBSTITUTE(G7,";",REPT(" ",99)),298,99))="","",IFERROR(VLOOKUP(--LEFT(TRIM(MID(SUBSTITUTE(G7,";",REPT(" ",99)),298,99)),FIND(":",TRIM(MID(SUBSTITUTE(G7,";",REPT(" ",99)),298,99)))-1),_Lookup!$A:$B,2,FALSE),"?")&"×"&MID(TRIM(MID(SUBSTITUTE(G7,";",REPT(" ",99)),298,99)),FIND(":",TRIM(MID(SUBSTITUTE(G7,";",REPT(" ",99)),298,99)))+1,99)),IF(TRIM(MID(SUBSTITUTE(G7,";",REPT(" ",99)),397,99))="","",IFERROR(VLOOKUP(--LEFT(TRIM(MID(SUBSTITUTE(G7,";",REPT(" ",99)),397,99)),FIND(":",TRIM(MID(SUBSTITUTE(G7,";",REPT(" ",99)),397,99)))-1),_Lookup!$A:$B,2,FALSE),"?")&"×"&MID(TRIM(MID(SUBSTITUTE(G7,";",REPT(" ",99)),397,99)),FIND(":",TRIM(MID(SUBSTITUTE(G7,";",REPT(" ",99)),397,99)))+1,99))))
C8: =IFERROR(VLOOKUP(B8,ItemData_Equipment!$A:$B,2,FALSE),"") | H8: =IF(G8="","",TEXTJOIN("; ",TRUE,IF(TRIM(MID(SUBSTITUTE(G8,";",REPT(" ",99)),1,99))="","",IFERROR(VLOOKUP(--LEFT(TRIM(MID(SUBSTITUTE(G8,";",REPT(" ",99)),1,99)),FIND(":",TRIM(MID(SUBSTITUTE(G8,";",REPT(" ",99)),1,99)))-1),_Lookup!$A:$B,2,FALSE),"?")&"×"&MID(TRIM(MID(SUBSTITUTE(G8,";",REPT(" ",99)),1,99)),FIND(":",TRIM(MID(SUBSTITUTE(G8,";",REPT(" ",99)),1,99)))+1,99)),IF(TRIM(MID(SUBSTITUTE(G8,";",REPT(" ",99)),100,99))="","",IFERROR(VLOOKUP(--LEFT(TRIM(MID(SUBSTITUTE(G8,";",REPT(" ",99)),100,99)),FIND(":",TRIM(MID(SUBSTITUTE(G8,";",REPT(" ",99)),100,99)))-1),_Lookup!$A:$B,2,FALSE),"?")&"×"&MID(TRIM(MID(SUBSTITUTE(G8,";",REPT(" ",99)),100,99)),FIND(":",TRIM(MID(SUBSTITUTE(G8,";",REPT(" ",99)),100,99)))+1,99)),IF(TRIM(MID(SUBSTITUTE(G8,";",REPT(" ",99)),199,99))="","",IFERROR(VLOOKUP(--LEFT(TRIM(MID(SUBSTITUTE(G8,";",REPT(" ",99)),199,99)),FIND(":",TRIM(MID(SUBSTITUTE(G8,";",REPT(" ",99)),199,99)))-1),_Lookup!$A:$B,2,FALSE),"?")&"×"&MID(TRIM(MID(SUBSTITUTE(G8,";",REPT(" ",99)),199,99)),FIND(":",TRIM(MID(SUBSTITUTE(G8,";",REPT(" ",99)),199,99)))+1,99)),IF(TRIM(MID(SUBSTITUTE(G8,";",REPT(" ",99)),298,99))="","",IFERROR(VLOOKUP(--LEFT(TRIM(MID(SUBSTITUTE(G8,";",REPT(" ",99)),298,99)),FIND(":",TRIM(MID(SUBSTITUTE(G8,";",REPT(" ",99)),298,99)))-1),_Lookup!$A:$B,2,FALSE),"?")&"×"&MID(TRIM(MID(SUBSTITUTE(G8,";",REPT(" ",99)),298,99)),FIND(":",TRIM(MID(SUBSTITUTE(G8,";",REPT(" ",99)),298,99)))+1,99)),IF(TRIM(MID(SUBSTITUTE(G8,";",REPT(" ",99)),397,99))="","",IFERROR(VLOOKUP(--LEFT(TRIM(MID(SUBSTITUTE(G8,";",REPT(" ",99)),397,99)),FIND(":",TRIM(MID(SUBSTITUTE(G8,";",REPT(" ",99)),397,99)))-1),_Lookup!$A:$B,2,FALSE),"?")&"×"&MID(TRIM(MID(SUBSTITUTE(G8,";",REPT(" ",99)),397,99)),FIND(":",TRIM(MID(SUBSTITUTE(G8,";",REPT(" ",99)),397,99)))+1,99))))
C9: =IFERROR(VLOOKUP(B9,ItemData_Equipment!$A:$B,2,FALSE),"") | H9: =IF(G9="","",TEXTJOIN("; ",TRUE,IF(TRIM(MID(SUBSTITUTE(G9,";",REPT(" ",99)),1,99))="","",IFERROR(VLOOKUP(--LEFT(TRIM(MID(SUBSTITUTE(G9,";",REPT(" ",99)),1,99)),FIND(":",TRIM(MID(SUBSTITUTE(G9,";",REPT(" ",99)),1,99)))-1),_Lookup!$A:$B,2,FALSE),"?")&"×"&MID(TRIM(MID(SUBSTITUTE(G9,";",REPT(" ",99)),1,99)),FIND(":",TRIM(MID(SUBSTITUTE(G9,";",REPT(" ",99)),1,99)))+1,99)),IF(TRIM(MID(SUBSTITUTE(G9,";",REPT(" ",99)),100,99))="","",IFERROR(VLOOKUP(--LEFT(TRIM(MID(SUBSTITUTE(G9,";",REPT(" ",99)),100,99)),FIND(":",TRIM(MID(SUBSTITUTE(G9,";",REPT(" ",99)),100,99)))-1),_Lookup!$A:$B,2,FALSE),"?")&"×"&MID(TRIM(MID(SUBSTITUTE(G9,";",REPT(" ",99)),100,99)),FIND(":",TRIM(MID(SUBSTITUTE(G9,";",REPT(" ",99)),100,99)))+1,99)),IF(TRIM(MID(SUBSTITUTE(G9,";",REPT(" ",99)),199,99))="","",IFERROR(VLOOKUP(--LEFT(TRIM(MID(SUBSTITUTE(G9,";",REPT(" ",99)),199,99)),FIND(":",TRIM(MID(SUBSTITUTE(G9,";",REPT(" ",99)),199,99)))-1),_Lookup!$A:$B,2,FALSE),"?")&"×"&MID(TRIM(MID(SUBSTITUTE(G9,";",REPT(" ",99)),199,99)),FIND(":",TRIM(MID(SUBSTITUTE(G9,";",REPT(" ",99)),199,99)))+1,99)),IF(TRIM(MID(SUBSTITUTE(G9,";",REPT(" ",99)),298,99))="","",IFERROR(VLOOKUP(--LEFT(TRIM(MID(SUBSTITUTE(G9,";",REPT(" ",99)),298,99)),FIND(":",TRIM(MID(SUBSTITUTE(G9,";",REPT(" ",99)),298,99)))-1),_Lookup!$A:$B,2,FALSE),"?")&"×"&MID(TRIM(MID(SUBSTITUTE(G9,";",REPT(" ",99)),298,99)),FIND(":",TRIM(MID(SUBSTITUTE(G9,";",REPT(" ",99)),298,99)))+1,99)),IF(TRIM(MID(SUBSTITUTE(G9,";",REPT(" ",99)),397,99))="","",IFERROR(VLOOKUP(--LEFT(TRIM(MID(SUBSTITUTE(G9,";",REPT(" ",99)),397,99)),FIND(":",TRIM(MID(SUBSTITUTE(G9,";",REPT(" ",99)),397,99)))-1),_Lookup!$A:$B,2,FALSE),"?")&"×"&MID(TRIM(MID(SUBSTITUTE(G9,";",REPT(" ",99)),397,99)),FIND(":",TRIM(MID(SUBSTITUTE(G9,";",REPT(" ",99)),397,99)))+1,99))))
C10: =IFERROR(VLOOKUP(B10,ItemData_Equipment!$A:$B,2,FALSE),"") | H10: =IF(G10="","",TEXTJOIN("; ",TRUE,IF(TRIM(MID(SUBSTITUTE(G10,";",REPT(" ",99)),1,99))="","",IFERROR(VLOOKUP(--LEFT(TRIM(MID(SUBSTITUTE(G10,";",REPT(" ",99)),1,99)),FIND(":",TRIM(MID(SUBSTITUTE(G10,";",REPT(" ",99)),1,99)))-1),_Lookup!$A:$B,2,FALSE),"?")&"×"&MID(TRIM(MID(SUBSTITUTE(G10,";",REPT(" ",99)),1,99)),FIND(":",TRIM(MID(SUBSTITUTE(G10,";",REPT(" ",99)),1,99)))+1,99)),IF(TRIM(MID(SUBSTITUTE(G10,";",REPT(" ",99)),100,99))="","",IFERROR(VLOOKUP(--LEFT(TRIM(MID(SUBSTITUTE(G10,";",REPT(" ",99)),100,99)),FIND(":",TRIM(MID(SUBSTITUTE(G10,";",REPT(" ",99)),100,99)))-1),_Lookup!$A:$B,2,FALSE),"?")&"×"&MID(TRIM(MID(SUBSTITUTE(G10,";",REPT(" ",99)),100,99)),FIND(":",TRIM(MID(SUBSTITUTE(G10,";",REPT(" ",99)),100,99)))+1,99)),IF(TRIM(MID(SUBSTITUTE(G10,";",REPT(" ",99)),199,99))="","",IFERROR(VLOOKUP(--LEFT(TRIM(MID(SUBSTITUTE(G10,";",REPT(" ",99)),199,99)),FIND(":",TRIM(MID(SUBSTITUTE(G10,";",REPT(" ",99)),199,99)))-1),_Lookup!$A:$B,2,FALSE),"?")&"×"&MID(TRIM(MID(SUBSTITUTE(G10,";",REPT(" ",99)),199,99)),FIND(":",TRIM(MID(SUBSTITUTE(G10,";",REPT(" ",99)),199,99)))+1,99)),IF(TRIM(MID(SUBSTITUTE(G10,";",REPT(" ",99)),298,99))="","",IFERROR(VLOOKUP(--LEFT(TRIM(MID(SUBSTITUTE(G10,";",REPT(" ",99)),298,99)),FIND(":",TRIM(MID(SUBSTITUTE(G10,";",REPT(" ",99)),298,99)))-1),_Lookup!$A:$B,2,FALSE),"?")&"×"&MID(TRIM(MID(SUBSTITUTE(G10,";",REPT(" ",99)),298,99)),FIND(":",TRIM(MID(SUBSTITUTE(G10,";",REPT(" ",99)),298,99)))+1,99)),IF(TRIM(MID(SUBSTITUTE(G10,";",REPT(" ",99)),397,99))="","",IFERROR(VLOOKUP(--LEFT(TRIM(MID(SUBSTITUTE(G10,";",REPT(" ",99)),397,99)),FIND(":",TRIM(MID(SUBSTITUTE(G10,";",REPT(" ",99)),397,99)))-1),_Lookup!$A:$B,2,FALSE),"?")&"×"&MID(TRIM(MID(SUBSTITUTE(G10,";",REPT(" ",99)),397,99)),FIND(":",TRIM(MID(SUBSTITUTE(G10,";",REPT(" ",99)),397,99)))+1,99))))
C11: =IFERROR(VLOOKUP(B11,ItemData_Equipment!$A:$B,2,FALSE),"") | H11: =IF(G11="","",TEXTJOIN("; ",TRUE,IF(TRIM(MID(SUBSTITUTE(G11,";",REPT(" ",99)),1,99))="","",IFERROR(VLOOKUP(--LEFT(TRIM(MID(SUBSTITUTE(G11,";",REPT(" ",99)),1,99)),FIND(":",TRIM(MID(SUBSTITUTE(G11,";",REPT(" ",99)),1,99)))-1),_Lookup!$A:$B,2,FALSE),"?")&"×"&MID(TRIM(MID(SUBSTITUTE(G11,";",REPT(" ",99)),1,99)),FIND(":",TRIM(MID(SUBSTITUTE(G11,";",REPT(" ",99)),1,99)))+1,99)),IF(TRIM(MID(SUBSTITUTE(G11,";",REPT(" ",99)),100,99))="","",IFERROR(VLOOKUP(--LEFT(TRIM(MID(SUBSTITUTE(G11,";",REPT(" ",99)),100,99)),FIND(":",TRIM(MID(SUBSTITUTE(G11,";",REPT(" ",99)),100,99)))-1),_Lookup!$A:$B,2,FALSE),"?")&"×"&MID(TRIM(MID(SUBSTITUTE(G11,";",REPT(" ",99)),100,99)),FIND(":",TRIM(MID(SUBSTITUTE(G11,";",REPT(" ",99)),100,99)))+1,99)),IF(TRIM(MID(SUBSTITUTE(G11,";",REPT(" ",99)),199,99))="","",IFERROR(VLOOKUP(--LEFT(TRIM(MID(SUBSTITUTE(G11,";",REPT(" ",99)),199,99)),FIND(":",TRIM(MID(SUBSTITUTE(G11,";",REPT(" ",99)),199,99)))-1),_Lookup!$A:$B,2,FALSE),"?")&"×"&MID(TRIM(MID(SUBSTITUTE(G11,";",REPT(" ",99)),199,99)),FIND(":",TRIM(MID(SUBSTITUTE(G11,";",REPT(" ",99)),199,99)))+1,99)),IF(TRIM(MID(SUBSTITUTE(G11,";",REPT(" ",99)),298,99))="","",IFERROR(VLOOKUP(--LEFT(TRIM(MID(SUBSTITUTE(G11,";",REPT(" ",99)),298,99)),FIND(":",TRIM(MID(SUBSTITUTE(G11,";",REPT(" ",99)),298,99)))-1),_Lookup!$A:$B,2,FALSE),"?")&"×"&MID(TRIM(MID(SUBSTITUTE(G11,";",REPT(" ",99)),298,99)),FIND(":",TRIM(MID(SUBSTITUTE(G11,";",REPT(" ",99)),298,99)))+1,99)),IF(TRIM(MID(SUBSTITUTE(G11,";",REPT(" ",99)),397,99))="","",IFERROR(VLOOKUP(--LEFT(TRIM(MID(SUBSTITUTE(G11,";",REPT(" ",99)),397,99)),FIND(":",TRIM(MID(SUBSTITUTE(G11,";",REPT(" ",99)),397,99)))-1),_Lookup!$A:$B,2,FALSE),"?")&"×"&MID(TRIM(MID(SUBSTITUTE(G11,";",REPT(" ",99)),397,99)),FIND(":",TRIM(MID(SUBSTITUTE(G11,";",REPT(" ",99)),397,99)))+1,99))))
C12: =IFERROR(VLOOKUP(B12,ItemData_Equipment!$A:$B,2,FALSE),"") | H12: =IF(G12="","",TEXTJOIN("; ",TRUE,IF(TRIM(MID(SUBSTITUTE(G12,";",REPT(" ",99)),1,99))="","",IFERROR(VLOOKUP(--LEFT(TRIM(MID(SUBSTITUTE(G12,";",REPT(" ",99)),1,99)),FIND(":",TRIM(MID(SUBSTITUTE(G12,";",REPT(" ",99)),1,99)))-1),_Lookup!$A:$B,2,FALSE),"?")&"×"&MID(TRIM(MID(SUBSTITUTE(G12,";",REPT(" ",99)),1,99)),FIND(":",TRIM(MID(SUBSTITUTE(G12,";",REPT(" ",99)),1,99)))+1,99)),IF(TRIM(MID(SUBSTITUTE(G12,";",REPT(" ",99)),100,99))="","",IFERROR(VLOOKUP(--LEFT(TRIM(MID(SUBSTITUTE(G12,";",REPT(" ",99)),100,99)),FIND(":",TRIM(MID(SUBSTITUTE(G12,";",REPT(" ",99)),100,99)))-1),_Lookup!$A:$B,2,FALSE),"?")&"×"&MID(TRIM(MID(SUBSTITUTE(G12,";",REPT(" ",99)),100,99)),FIND(":",TRIM(MID(SUBSTITUTE(G12,";",REPT(" ",99)),100,99)))+1,99)),IF(TRIM(MID(SUBSTITUTE(G12,";",REPT(" ",99)),199,99))="","",IFERROR(VLOOKUP(--LEFT(TRIM(MID(SUBSTITUTE(G12,";",REPT(" ",99)),199,99)),FIND(":",TRIM(MID(SUBSTITUTE(G12,";",REPT(" ",99)),199,99)))-1),_Lookup!$A:$B,2,FALSE),"?")&"×"&MID(TRIM(MID(SUBSTITUTE(G12,";",REPT(" ",99)),199,99)),FIND(":",TRIM(MID(SUBSTITUTE(G12,";",REPT(" ",99)),199,99)))+1,99)),IF(TRIM(MID(SUBSTITUTE(G12,";",REPT(" ",99)),298,99))="","",IFERROR(VLOOKUP(--LEFT(TRIM(MID(SUBSTITUTE(G12,";",REPT(" ",99)),298,99)),FIND(":",TRIM(MID(SUBSTITUTE(G12,";",REPT(" ",99)),298,99)))-1),_Lookup!$A:$B,2,FALSE),"?")&"×"&MID(TRIM(MID(SUBSTITUTE(G12,";",REPT(" ",99)),298,99)),FIND(":",TRIM(MID(SUBSTITUTE(G12,";",REPT(" ",99)),298,99)))+1,99)),IF(TRIM(MID(SUBSTITUTE(G12,";",REPT(" ",99)),397,99))="","",IFERROR(VLOOKUP(--LEFT(TRIM(MID(SUBSTITUTE(G12,";",REPT(" ",99)),397,99)),FIND(":",TRIM(MID(SUBSTITUTE(G12,";",REPT(" ",99)),397,99)))-1),_Lookup!$A:$B,2,FALSE),"?")&"×"&MID(TRIM(MID(SUBSTITUTE(G12,";",REPT(" ",99)),397,99)),FIND(":",TRIM(MID(SUBSTITUTE(G12,";",REPT(" ",99)),397,99)))+1,99))))
C13: =IFERROR(VLOOKUP(B13,ItemData_Equipment!$A:$B,2,FALSE),"") | H13: =IF(G13="","",TEXTJOIN("; ",TRUE,IF(TRIM(MID(SUBSTITUTE(G13,";",REPT(" ",99)),1,99))="","",IFERROR(VLOOKUP(--LEFT(TRIM(MID(SUBSTITUTE(G13,";",REPT(" ",99)),1,99)),FIND(":",TRIM(MID(SUBSTITUTE(G13,";",REPT(" ",99)),1,99)))-1),_Lookup!$A:$B,2,FALSE),"?")&"×"&MID(TRIM(MID(SUBSTITUTE(G13,";",REPT(" ",99)),1,99)),FIND(":",TRIM(MID(SUBSTITUTE(G13,";",REPT(" ",99)),1,99)))+1,99)),IF(TRIM(MID(SUBSTITUTE(G13,";",REPT(" ",99)),100,99))="","",IFERROR(VLOOKUP(--LEFT(TRIM(MID(SUBSTITUTE(G13,";",REPT(" ",99)),100,99)),FIND(":",TRIM(MID(SUBSTITUTE(G13,";",REPT(" ",99)),100,99)))-1),_Lookup!$A:$B,2,FALSE),"?")&"×"&MID(TRIM(MID(SUBSTITUTE(G13,";",REPT(" ",99)),100,99)),FIND(":",TRIM(MID(SUBSTITUTE(G13,";",REPT(" ",99)),100,99)))+1,99)),IF(TRIM(MID(SUBSTITUTE(G13,";",REPT(" ",99)),199,99))="","",IFERROR(VLOOKUP(--LEFT(TRIM(MID(SUBSTITUTE(G13,";",REPT(" ",99)),199,99)),FIND(":",TRIM(MID(SUBSTITUTE(G13,";",REPT(" ",99)),199,99)))-1),_Lookup!$A:$B,2,FALSE),"?")&"×"&MID(TRIM(MID(SUBSTITUTE(G13,";",REPT(" ",99)),199,99)),FIND(":",TRIM(MID(SUBSTITUTE(G13,";",REPT(" ",99)),199,99)))+1,99)),IF(TRIM(MID(SUBSTITUTE(G13,";",REPT(" ",99)),298,99))="","",IFERROR(VLOOKUP(--LEFT(TRIM(MID(SUBSTITUTE(G13,";",REPT(" ",99)),298,99)),FIND(":",TRIM(MID(SUBSTITUTE(G13,";",REPT(" ",99)),298,99)))-1),_Lookup!$A:$B,2,FALSE),"?")&"×"&MID(TRIM(MID(SUBSTITUTE(G13,";",REPT(" ",99)),298,99)),FIND(":",TRIM(MID(SUBSTITUTE(G13,";",REPT(" ",99)),298,99)))+1,99)),IF(TRIM(MID(SUBSTITUTE(G13,";",REPT(" ",99)),397,99))="","",IFERROR(VLOOKUP(--LEFT(TRIM(MID(SUBSTITUTE(G13,";",REPT(" ",99)),397,99)),FIND(":",TRIM(MID(SUBSTITUTE(G13,";",REPT(" ",99)),397,99)))-1),_Lookup!$A:$B,2,FALSE),"?")&"×"&MID(TRIM(MID(SUBSTITUTE(G13,";",REPT(" ",99)),397,99)),FIND(":",TRIM(MID(SUBSTITUTE(G13,";",REPT(" ",99)),397,99)))+1,99))))
C14: =IFERROR(VLOOKUP(B14,ItemData_Equipment!$A:$B,2,FALSE),"") | H14: =IF(G14="","",TEXTJOIN("; ",TRUE,IF(TRIM(MID(SUBSTITUTE(G14,";",REPT(" ",99)),1,99))="","",IFERROR(VLOOKUP(--LEFT(TRIM(MID(SUBSTITUTE(G14,";",REPT(" ",99)),1,99)),FIND(":",TRIM(MID(SUBSTITUTE(G14,";",REPT(" ",99)),1,99)))-1),_Lookup!$A:$B,2,FALSE),"?")&"×"&MID(TRIM(MID(SUBSTITUTE(G14,";",REPT(" ",99)),1,99)),FIND(":",TRIM(MID(SUBSTITUTE(G14,";",REPT(" ",99)),1,99)))+1,99)),IF(TRIM(MID(SUBSTITUTE(G14,";",REPT(" ",99)),100,99))="","",IFERROR(VLOOKUP(--LEFT(TRIM(MID(SUBSTITUTE(G14,";",REPT(" ",99)),100,99)),FIND(":",TRIM(MID(SUBSTITUTE(G14,";",REPT(" ",99)),100,99)))-1),_Lookup!$A:$B,2,FALSE),"?")&"×"&MID(TRIM(MID(SUBSTITUTE(G14,";",REPT(" ",99)),100,99)),FIND(":",TRIM(MID(SUBSTITUTE(G14,";",REPT(" ",99)),100,99)))+1,99)),IF(TRIM(MID(SUBSTITUTE(G14,";",REPT(" ",99)),199,99))="","",IFERROR(VLOOKUP(--LEFT(TRIM(MID(SUBSTITUTE(G14,";",REPT(" ",99)),199,99)),FIND(":",TRIM(MID(SUBSTITUTE(G14,";",REPT(" ",99)),199,99)))-1),_Lookup!$A:$B,2,FALSE),"?")&"×"&MID(TRIM(MID(SUBSTITUTE(G14,";",REPT(" ",99)),199,99)),FIND(":",TRIM(MID(SUBSTITUTE(G14,";",REPT(" ",99)),199,99)))+1,99)),IF(TRIM(MID(SUBSTITUTE(G14,";",REPT(" ",99)),298,99))="","",IFERROR(VLOOKUP(--LEFT(TRIM(MID(SUBSTITUTE(G14,";",REPT(" ",99)),298,99)),FIND(":",TRIM(MID(SUBSTITUTE(G14,";",REPT(" ",99)),298,99)))-1),_Lookup!$A:$B,2,FALSE),"?")&"×"&MID(TRIM(MID(SUBSTITUTE(G14,";",REPT(" ",99)),298,99)),FIND(":",TRIM(MID(SUBSTITUTE(G14,";",REPT(" ",99)),298,99)))+1,99)),IF(TRIM(MID(SUBSTITUTE(G14,";",REPT(" ",99)),397,99))="","",IFERROR(VLOOKUP(--LEFT(TRIM(MID(SUBSTITUTE(G14,";",REPT(" ",99)),397,99)),FIND(":",TRIM(MID(SUBSTITUTE(G14,";",REPT(" ",99)),397,99)))-1),_Lookup!$A:$B,2,FALSE),"?")&"×"&MID(TRIM(MID(SUBSTITUTE(G14,";",REPT(" ",99)),397,99)),FIND(":",TRIM(MID(SUBSTITUTE(G14,";",REPT(" ",99)),397,99)))+1,99))))
C15: =IFERROR(VLOOKUP(B15,ItemData_Equipment!$A:$B,2,FALSE),"") | H15: =IF(G15="","",TEXTJOIN("; ",TRUE,IF(TRIM(MID(SUBSTITUTE(G15,";",REPT(" ",99)),1,99))="","",IFERROR(VLOOKUP(--LEFT(TRIM(MID(SUBSTITUTE(G15,";",REPT(" ",99)),1,99)),FIND(":",TRIM(MID(SUBSTITUTE(G15,";",REPT(" ",99)),1,99)))-1),_Lookup!$A:$B,2,FALSE),"?")&"×"&MID(TRIM(MID(SUBSTITUTE(G15,";",REPT(" ",99)),1,99)),FIND(":",TRIM(MID(SUBSTITUTE(G15,";",REPT(" ",99)),1,99)))+1,99)),IF(TRIM(MID(SUBSTITUTE(G15,";",REPT(" ",99)),100,99))="","",IFERROR(VLOOKUP(--LEFT(TRIM(MID(SUBSTITUTE(G15,";",REPT(" ",99)),100,99)),FIND(":",TRIM(MID(SUBSTITUTE(G15,";",REPT(" ",99)),100,99)))-1),_Lookup!$A:$B,2,FALSE),"?")&"×"&MID(TRIM(MID(SUBSTITUTE(G15,";",REPT(" ",99)),100,99)),FIND(":",TRIM(MID(SUBSTITUTE(G15,";",REPT(" ",99)),100,99)))+1,99)),IF(TRIM(MID(SUBSTITUTE(G15,";",REPT(" ",99)),199,99))="","",IFERROR(VLOOKUP(--LEFT(TRIM(MID(SUBSTITUTE(G15,";",REPT(" ",99)),199,99)),FIND(":",TRIM(MID(SUBSTITUTE(G15,";",REPT(" ",99)),199,99)))-1),_Lookup!$A:$B,2,FALSE),"?")&"×"&MID(TRIM(MID(SUBSTITUTE(G15,";",REPT(" ",99)),199,99)),FIND(":",TRIM(MID(SUBSTITUTE(G15,";",REPT(" ",99)),199,99)))+1,99)),IF(TRIM(MID(SUBSTITUTE(G15,";",REPT(" ",99)),298,99))="","",IFERROR(VLOOKUP(--LEFT(TRIM(MID(SUBSTITUTE(G15,";",REPT(" ",99)),298,99)),FIND(":",TRIM(MID(SUBSTITUTE(G15,";",REPT(" ",99)),298,99)))-1),_Lookup!$A:$B,2,FALSE),"?")&"×"&MID(TRIM(MID(SUBSTITUTE(G15,";",REPT(" ",99)),298,99)),FIND(":",TRIM(MID(SUBSTITUTE(G15,";",REPT(" ",99)),298,99)))+1,99)),IF(TRIM(MID(SUBSTITUTE(G15,";",REPT(" ",99)),397,99))="","",IFERROR(VLOOKUP(--LEFT(TRIM(MID(SUBSTITUTE(G15,";",REPT(" ",99)),397,99)),FIND(":",TRIM(MID(SUBSTITUTE(G15,";",REPT(" ",99)),397,99)))-1),_Lookup!$A:$B,2,FALSE),"?")&"×"&MID(TRIM(MID(SUBSTITUTE(G15,";",REPT(" ",99)),397,99)),FIND(":",TRIM(MID(SUBSTITUTE(G15,";",REPT(" ",99)),397,99)))+1,99))))
C16: =IFERROR(VLOOKUP(B16,ItemData_Equipment!$A:$B,2,FALSE),"") | H16: =IF(G16="","",TEXTJOIN("; ",TRUE,IF(TRIM(MID(SUBSTITUTE(G16,";",REPT(" ",99)),1,99))="","",IFERROR(VLOOKUP(--LEFT(TRIM(MID(SUBSTITUTE(G16,";",REPT(" ",99)),1,99)),FIND(":",TRIM(MID(SUBSTITUTE(G16,";",REPT(" ",99)),1,99)))-1),_Lookup!$A:$B,2,FALSE),"?")&"×"&MID(TRIM(MID(SUBSTITUTE(G16,";",REPT(" ",99)),1,99)),FIND(":",TRIM(MID(SUBSTITUTE(G16,";",REPT(" ",99)),1,99)))+1,99)),IF(TRIM(MID(SUBSTITUTE(G16,";",REPT(" ",99)),100,99))="","",IFERROR(VLOOKUP(--LEFT(TRIM(MID(SUBSTITUTE(G16,";",REPT(" ",99)),100,99)),FIND(":",TRIM(MID(SUBSTITUTE(G16,";",REPT(" ",99)),100,99)))-1),_Lookup!$A:$B,2,FALSE),"?")&"×"&MID(TRIM(MID(SUBSTITUTE(G16,";",REPT(" ",99)),100,99)),FIND(":",TRIM(MID(SUBSTITUTE(G16,";",REPT(" ",99)),100,99)))+1,99)),IF(TRIM(MID(SUBSTITUTE(G16,";",REPT(" ",99)),199,99))="","",IFERROR(VLOOKUP(--LEFT(TRIM(MID(SUBSTITUTE(G16,";",REPT(" ",99)),199,99)),FIND(":",TRIM(MID(SUBSTITUTE(G16,";",REPT(" ",99)),199,99)))-1),_Lookup!$A:$B,2,FALSE),"?")&"×"&MID(TRIM(MID(SUBSTITUTE(G16,";",REPT(" ",99)),199,99)),FIND(":",TRIM(MID(SUBSTITUTE(G16,";",REPT(" ",99)),199,99)))+1,99)),IF(TRIM(MID(SUBSTITUTE(G16,";",REPT(" ",99)),298,99))="","",IFERROR(VLOOKUP(--LEFT(TRIM(MID(SUBSTITUTE(G16,";",REPT(" ",99)),298,99)),FIND(":",TRIM(MID(SUBSTITUTE(G16,";",REPT(" ",99)),298,99)))-1),_Lookup!$A:$B,2,FALSE),"?")&"×"&MID(TRIM(MID(SUBSTITUTE(G16,";",REPT(" ",99)),298,99)),FIND(":",TRIM(MID(SUBSTITUTE(G16,";",REPT(" ",99)),298,99)))+1,99)),IF(TRIM(MID(SUBSTITUTE(G16,";",REPT(" ",99)),397,99))="","",IFERROR(VLOOKUP(--LEFT(TRIM(MID(SUBSTITUTE(G16,";",REPT(" ",99)),397,99)),FIND(":",TRIM(MID(SUBSTITUTE(G16,";",REPT(" ",99)),397,99)))-1),_Lookup!$A:$B,2,FALSE),"?")&"×"&MID(TRIM(MID(SUBSTITUTE(G16,";",REPT(" ",99)),397,99)),FIND(":",TRIM(MID(SUBSTITUTE(G16,";",REPT(" ",99)),397,99)))+1,99))))
C17: =IFERROR(VLOOKUP(B17,ItemData_Equipment!$A:$B,2,FALSE),"") | H17: =IF(G17="","",TEXTJOIN("; ",TRUE,IF(TRIM(MID(SUBSTITUTE(G17,";",REPT(" ",99)),1,99))="","",IFERROR(VLOOKUP(--LEFT(TRIM(MID(SUBSTITUTE(G17,";",REPT(" ",99)),1,99)),FIND(":",TRIM(MID(SUBSTITUTE(G17,";",REPT(" ",99)),1,99)))-1),_Lookup!$A:$B,2,FALSE),"?")&"×"&MID(TRIM(MID(SUBSTITUTE(G17,";",REPT(" ",99)),1,99)),FIND(":",TRIM(MID(SUBSTITUTE(G17,";",REPT(" ",99)),1,99)))+1,99)),IF(TRIM(MID(SUBSTITUTE(G17,";",REPT(" ",99)),100,99))="","",IFERROR(VLOOKUP(--LEFT(TRIM(MID(SUBSTITUTE(G17,";",REPT(" ",99)),100,99)),FIND(":",TRIM(MID(SUBSTITUTE(G17,";",REPT(" ",99)),100,99)))-1),_Lookup!$A:$B,2,FALSE),"?")&"×"&MID(TRIM(MID(SUBSTITUTE(G17,";",REPT(" ",99)),100,99)),FIND(":",TRIM(MID(SUBSTITUTE(G17,";",REPT(" ",99)),100,99)))+1,99)),IF(TRIM(MID(SUBSTITUTE(G17,";",REPT(" ",99)),199,99))="","",IFERROR(VLOOKUP(--LEFT(TRIM(MID(SUBSTITUTE(G17,";",REPT(" ",99)),199,99)),FIND(":",TRIM(MID(SUBSTITUTE(G17,";",REPT(" ",99)),199,99)))-1),_Lookup!$A:$B,2,FALSE),"?")&"×"&MID(TRIM(MID(SUBSTITUTE(G17,";",REPT(" ",99)),199,99)),FIND(":",TRIM(MID(SUBSTITUTE(G17,";",REPT(" ",99)),199,99)))+1,99)),IF(TRIM(MID(SUBSTITUTE(G17,";",REPT(" ",99)),298,99))="","",IFERROR(VLOOKUP(--LEFT(TRIM(MID(SUBSTITUTE(G17,";",REPT(" ",99)),298,99)),FIND(":",TRIM(MID(SUBSTITUTE(G17,";",REPT(" ",99)),298,99)))-1),_Lookup!$A:$B,2,FALSE),"?")&"×"&MID(TRIM(MID(SUBSTITUTE(G17,";",REPT(" ",99)),298,99)),FIND(":",TRIM(MID(SUBSTITUTE(G17,";",REPT(" ",99)),298,99)))+1,99)),IF(TRIM(MID(SUBSTITUTE(G17,";",REPT(" ",99)),397,99))="","",IFERROR(VLOOKUP(--LEFT(TRIM(MID(SUBSTITUTE(G17,";",REPT(" ",99)),397,99)),FIND(":",TRIM(MID(SUBSTITUTE(G17,";",REPT(" ",99)),397,99)))-1),_Lookup!$A:$B,2,FALSE),"?")&"×"&MID(TRIM(MID(SUBSTITUTE(G17,";",REPT(" ",99)),397,99)),FIND(":",TRIM(MID(SUBSTITUTE(G17,";",REPT(" ",99)),397,99)))+1,99))))
... C300: =IFERROR(VLOOKUP(B300,ItemData_Equipment!$A:$B,2,FALSE),"") | H300: =IF(G300="","",TEXTJOIN("; ",TRUE,IF(TRIM(MID(SUBSTITUTE(G300,";",REPT(" ",99)),1,99))="","",IFERROR(VLOOKUP(--LEFT(TRIM(MID(SUBSTITUTE(G300,";",REPT(" ",99)),1,99)),FIND(":",TRIM(MID(SUBSTITUTE(G300,";",REPT(" ",99)),1,99)))-1),_Lookup!$A:$B,2,FALSE),"?")&"×"&MID(TRIM(MID(SUBSTITUTE(G300,";",REPT(" ",99)),1,99)),FIND(":",TRIM(MID(SUBSTITUTE(G300,";",REPT(" ",99)),1,99)))+1,99)),IF(TRIM(MID(SUBSTITUTE(G300,";",REPT(" ",99)),100,99))="","",IFERROR(VLOOKUP(--LEFT(TRIM(MID(SUBSTITUTE(G300,";",REPT(" ",99)),100,99)),FIND(":",TRIM(MID(SUBSTITUTE(G300,";",REPT(" ",99)),100,99)))-1),_Lookup!$A:$B,2,FALSE),"?")&"×"&MID(TRIM(MID(SUBSTITUTE(G300,";",REPT(" ",99)),100,99)),FIND(":",TRIM(MID(SUBSTITUTE(G300,";",REPT(" ",99)),100,99)))+1,99)),IF(TRIM(MID(SUBSTITUTE(G300,";",REPT(" ",99)),199,99))="","",IFERROR(VLOOKUP(--LEFT(TRIM(MID(SUBSTITUTE(G300,";",REPT(" ",99)),199,99)),FIND(":",TRIM(MID(SUBSTITUTE(G300,";",REPT(" ",99)),199,99)))-1),_Lookup!$A:$B,2,FALSE),"?")&"×"&MID(TRIM(MID(SUBSTITUTE(G300,";",REPT(" ",99)),199,99)),FIND(":",TRIM(MID(SUBSTITUTE(G300,";",REPT(" ",99)),199,99)))+1,99)),IF(TRIM(MID(SUBSTITUTE(G300,";",REPT(" ",99)),298,99))="","",IFERROR(VLOOKUP(--LEFT(TRIM(MID(SUBSTITUTE(G300,";",REPT(" ",99)),298,99)),FIND(":",TRIM(MID(SUBSTITUTE(G300,";",REPT(" ",99)),298,99)))-1),_Lookup!$A:$B,2,FALSE),"?")&"×"&MID(TRIM(MID(SUBSTITUTE(G300,";",REPT(" ",99)),298,99)),FIND(":",TRIM(MID(SUBSTITUTE(G300,";",REPT(" ",99)),298,99)))+1,99)),IF(TRIM(MID(SUBSTITUTE(G300,";",REPT(" ",99)),397,99))="","",IFERROR(VLOOKUP(--LEFT(TRIM(MID(SUBSTITUTE(G300,";",REPT(" ",99)),397,99)),FIND(":",TRIM(MID(SUBSTITUTE(G300,";",REPT(" ",99)),397,99)))-1),_Lookup!$A:$B,2,FALSE),"?")&"×"&MID(TRIM(MID(SUBSTITUTE(G300,";",REPT(" ",99)),397,99)),FIND(":",TRIM(MID(SUBSTITUTE(G300,";",REPT(" ",99)),397,99)))+1,99))))

Sheet ItemData_Consumables
A1: m_id | B1: m_name | C1: m_type | D1: m_tier | E1: m_basePrice | F1: m_mountingArea | G1: m_modifiers | H1: m_summonTarget_id | I1: #summonTarget_name | J1: m_craftMaterials | K1: m_craftGoldCost | L1: m_assetKey
A2: 고유 ID (int) | B2: 이름 | C2: Consumables 고정 | D2: 티어 (int) | E2: 기준 판매가 | F2: Bait 또는 Groundbait | G2: 장착 중 효과 — 압축 | H2: 보스 소환 대상 (BattleFishData m_id, 빈칸=일반) | I2: 표시 전용(#) — JSON 변환 제외. 자동(VLOOKUP), 입력 금지 | J2: 제작 재료 — 압축: materialId:count;... | K2: 제작 골드 | L2: 에셋 키 오버라이드 — 빈칸=규약({클래스명}_{ID}). 여러 항목이 에셋을 공유하거나 스킨/예외일 때만 입력
A3: 400001 | B3: 새우 미끼 | C3: Consumables | D3: 1 | E3: 30 | F3: Bait | G3: ProbabilityAtFishSize:Add:0.1 | I3: =IFERROR(VLOOKUP(H3,BattleFishData!$A:$B,2,FALSE),"") | J3: 300002:3 | K3: 50
A4: 400002 | B4: 보스 소환 미끼 | C4: Consumables | D4: 1 | E4: 0 | F4: Bait | H4: 500002 | I4: =IFERROR(VLOOKUP(H4,BattleFishData!$A:$B,2,FALSE),"") | J4: 300001:5;300002:5 | K4: 200
I5: =IFERROR(VLOOKUP(H5,BattleFishData!$A:$B,2,FALSE),"")
I6: =IFERROR(VLOOKUP(H6,BattleFishData!$A:$B,2,FALSE),"")
I7: =IFERROR(VLOOKUP(H7,BattleFishData!$A:$B,2,FALSE),"")
I8: =IFERROR(VLOOKUP(H8,BattleFishData!$A:$B,2,FALSE),"")
I9: =IFERROR(VLOOKUP(H9,BattleFishData!$A:$B,2,FALSE),"")
I10: =IFERROR(VLOOKUP(H10,BattleFishData!$A:$B,2,FALSE),"")
I11: =IFERROR(VLOOKUP(H11,BattleFishData!$A:$B,2,FALSE),"")
I12: =IFERROR(VLOOKUP(H12,BattleFishData!$A:$B,2,FALSE),"")
I13: =IFERROR(VLOOKUP(H13,BattleFishData!$A:$B,2,FALSE),"")
I14: =IFERROR(VLOOKUP(H14,BattleFishData!$A:$B,2,FALSE),"")
I15: =IFERROR(VLOOKUP(H15,BattleFishData!$A:$B,2,FALSE),"")
I16: =IFERROR(VLOOKUP(H16,BattleFishData!$A:$B,2,FALSE),"")
... I300: =IFERROR(VLOOKUP(H300,BattleFishData!$A:$B,2,FALSE),"")

Sheet PlayerData
A1: m_id | B1: m_name | C1: m_baseDamagePerClick | D1: m_baseManualDamagePerHitMultiply | E1: m_baseBattleTimeVariable | F1: m_baseCriticalChance | G1: m_baseCriticalMultiply | H1: m_baseAutoBattleCooltime | I1: m_baseAutoSpeedPerTime | J1: m_baseAutoDamagePerHitMultiply | K1: m_baseProbabilityAtFishSize | L1: m_baseProbabilityAtFishRarity | M1: m_baseGoldGettingMultiply | N1: m_baseMapMovementSpeedPerTime | O1: m_baseInventorySize | P1: m_startingLicense | Q1: m_startingGold
A2: 고유 ID | B2: 이름 | C2: 클릭 공격력 | D2: 수동 배율 | E2: 전투 시간 변수 | F2: 크리 확률 | G2: 크리 배율 | H2: 자동 간격(초) | I2: 자동 초당 횟수 | J2: 자동 배율 | K2: 성급 확률 변수 | L2: 등급 확률 변수 | M2: 골드 배율 | N2: 이동속도 | O2: 인벤토리 칸 | P2: 시작 라이센스 | Q2: 시작 골드
A3: 1 | B3: Player | C3: 1 | D3: 1 | E3: 10 | F3: 0.05 | G3: 1.5 | H3: 5 | I3: 1 | J3: 1 | K3: 0 | L3: 0 | M3: 1 | N3: 10 | O3: 20 | P3: 1 | Q3: 0

Sheet BattleFishData
A1: m_id | B1: m_name | C1: m_itemFish_id | D1: #itemFish_name | E1: m_maxHp | F1: m_battleTimeVariable | G1: m_minSize | H1: m_maxSize | I1: m_qualityThresholds | J1: m_isBoss | K1: m_bossDrops | L1: #bossDrops_name | M1: m_assetKey
A2: 고유 ID (int) | B2: 이름 | C2: 포획 시 아이템 종 (ItemData_Fish m_id) | D2: 표시 전용(#) — JSON 변환 제외. 자동(VLOOKUP), 입력 금지 | E2: 최대 체력 | F2: 전투 시간 변수 | G2: 크기 롤 하한 | H2: 크기 롤 상한 | I2: 성급 경계 4개 오름차순 — v1;v2;v3;v4 | J2: 보스 여부 TRUE/FALSE | K2: 보스 드롭 — 압축: 타입:id:count:확률;... | L2: 표시 전용(#) — 압축 문자열 이름 해석(최대 5항목). 자동, 입력 금지 | M2: 에셋 키 오버라이드 — 빈칸=규약({클래스명}_{ID}). 여러 항목이 에셋을 공유하거나 스킨/예외일 때만 입력
A3: 500001 | B3: 고등어(전투) | C3: 100001 | D3: =IFERROR(VLOOKUP(C3,ItemData_Fish!$A:$B,2,FALSE),"") | E3: 100 | F3: 10 | G3: 20 | H3: 80 | I3: 32;44;56;68 | J3: FALSE | L3: =IF(K3="","",TEXTJOIN("; ",TRUE,IF(TRIM(MID(SUBSTITUTE(K3,";",REPT(" ",99)),1,99))="","",IFERROR(VLOOKUP(--LEFT(MID(TRIM(MID(SUBSTITUTE(K3,";",REPT(" ",99)),1,99)),FIND(":",TRIM(MID(SUBSTITUTE(K3,";",REPT(" ",99)),1,99)))+1,999),FIND(":",MID(TRIM(MID(SUBSTITUTE(K3,";",REPT(" ",99)),1,99)),FIND(":",TRIM(MID(SUBSTITUTE(K3,";",REPT(" ",99)),1,99)))+1,999))-1),_Lookup!$A:$B,2,FALSE),"?")&"×"&LEFT(MID(MID(TRIM(MID(SUBSTITUTE(K3,";",REPT(" ",99)),1,99)),FIND(":",TRIM(MID(SUBSTITUTE(K3,";",REPT(" ",99)),1,99)))+1,999),FIND(":",MID(TRIM(MID(SUBSTITUTE(K3,";",REPT(" ",99)),1,99)),FIND(":",TRIM(MID(SUBSTITUTE(K3,";",REPT(" ",99)),1,99)))+1,999))+1,999),FIND(":",MID(MID(TRIM(MID(SUBSTITUTE(K3,";",REPT(" ",99)),1,99)),FIND(":",TRIM(MID(SUBSTITUTE(K3,";",REPT(" ",99)),1,99)))+1,999),FIND(":",MID(TRIM(MID(SUBSTITUTE(K3,";",REPT(" ",99)),1,99)),FIND(":",TRIM(MID(SUBSTITUTE(K3,";",REPT(" ",99)),1,99)))+1,999))+1,999))-1)),IF(TRIM(MID(SUBSTITUTE(K3,";",REPT(" ",99)),100,99))="","",IFERROR(VLOOKUP(--LEFT(MID(TRIM(MID(SUBSTITUTE(K3,";",REPT(" ",99)),100,99)),FIND(":",TRIM(MID(SUBSTITUTE(K3,";",REPT(" ",99)),100,99)))+1,999),FIND(":",MID(TRIM(MID(SUBSTITUTE(K3,";",REPT(" ",99)),100,99)),FIND(":",TRIM(MID(SUBSTITUTE(K3,";",REPT(" ",99)),100,99)))+1,999))-1),_Lookup!$A:$B,2,FALSE),"?")&"×"&LEFT(MID(MID(TRIM(MID(SUBSTITUTE(K3,";",REPT(" ",99)),100,99)),FIND(":",TRIM(MID(SUBSTITUTE(K3,";",REPT(" ",99)),100,99)))+1,999),FIND(":",MID(TRIM(MID(SUBSTITUTE(K3,";",REPT(" ",99)),100,99)),FIND(":",TRIM(MID(SUBSTITUTE(K3,";",REPT(" ",99)),100,99)))+1,999))+1,999),FIND(":",MID(MID(TRIM(MID(SUBSTITUTE(K3,";",REPT(" ",99)),100,99)),FIND(":",TRIM(MID(SUBSTITUTE(K3,";",REPT(" ",99)),100,99)))+1,999),FIND(":",MID(TRIM(MID(SUBSTITUTE(K3,";",REPT(" ",99)),100,99)),FIND(":",TRIM(MID(SUBSTITUTE(K3,";",REPT(" ",99)),100,99)))+1,999))+1,999))-1)),IF(TRIM(MID(SUBSTITUTE(K3,";",REPT(" ",99)),199,99))="","",IFERROR(VLOOKUP(--LEFT(MID(TRIM(MID(SUBSTITUTE(K3,";",REPT(" ",99)),199,99)),FIND(":",TRIM(MID(SUBSTITUTE(K3,";",REPT(" ",99)),199,99)))+1,999),FIND(":",MID(TRIM(MID(SUBSTITUTE(K3,";",REPT(" ",99)),199,99)),FIND(":",TRIM(MID(SUBSTITUTE(K3,";",REPT(" ",99)),199,99)))+1,999))-1),_Lookup!$A:$B,2,FALSE),"?")&"×"&LEFT(MID(MID(TRIM(MID(SUBSTITUTE(K3,";",REPT(" ",99)),199,99)),FIND(":",TRIM(MID(SUBSTITUTE(K3,";",REPT(" ",99)),199,99)))+1,999),FIND(":",MID(TRIM(MID(SUBSTITUTE(K3,";",REPT(" ",99)),199,99)),FIND(":",TRIM(MID(SUBSTITUTE(K3,";",REPT(" ",99)),199,99)))+1,999))+1,999),FIND(":",MID(MID(TRIM(MID(SUBSTITUTE(K3,";",REPT(" ",99)),199,99)),FIND(":",TRIM(MID(SUBSTITUTE(K3,";",REPT(" ",99)),199,99)))+1,999),FIND(":",MID(TRIM(MID(SUBSTITUTE(K3,";",REPT(" ",99)),199,99)),FIND(":",TRIM(MID(SUBSTITUTE(K3,";",REPT(" ",99)),199,99)))+1,999))+1,999))-1)),IF(TRIM(MID(SUBSTITUTE(K3,";",REPT(" ",99)),298,99))="","",IFERROR(VLOOKUP(--LEFT(MID(TRIM(MID(SUBSTITUTE(K3,";",REPT(" ",99)),298,99)),FIND(":",TRIM(MID(SUBSTITUTE(K3,";",REPT(" ",99)),298,99)))+1,999),FIND(":",MID(TRIM(MID(SUBSTITUTE(K3,";",REPT(" ",99)),298,99)),FIND(":",TRIM(MID(SUBSTITUTE(K3,";",REPT(" ",99)),298,99)))+1,999))-1),_Lookup!$A:$B,2,FALSE),"?")&"×"&LEFT(MID(MID(TRIM(MID(SUBSTITUTE(K3,";",REPT(" ",99)),298,99)),FIND(":",TRIM(MID(SUBSTITUTE(K3,";",REPT(" ",99)),298,99)))+1,999),FIND(":",MID(TRIM(MID(SUBSTITUTE(K3,";",REPT(" ",99)),298,99)),FIND(":",TRIM(MID(SUBSTITUTE(K3,";",REPT(" ",99)),298,99)))+1,999))+1,999),FIND(":",MID(MID(TRIM(MID(SUBSTITUTE(K3,";",REPT(" ",99)),298,99)),FIND(":",TRIM(MID(SUBSTITUTE(K3,";",REPT(" ",99)),298,99)))+1,999),FIND(":",MID(TRIM(MID(SUBSTITUTE(K3,";",REPT(" ",99)),298,99)),FIND(":",TRIM(MID(SUBSTITUTE(K3,";",REPT(" ",99)),298,99)))+1,999))+1,999))-1)),IF(TRIM(MID(SUBSTITUTE(K3,";",REPT(" ",99)),397,99))="","",IFERROR(VLOOKUP(--LEFT(MID(TRIM(MID(SUBSTITUTE(K3,";",REPT(" ",99)),397,99)),FIND(":",TRIM(MID(SUBSTITUTE(K3,";",REPT(" ",99)),397,99)))+1,999),FIND(":",MID(TRIM(MID(SUBSTITUTE(K3,";",REPT(" ",99)),397,99)),FIND(":",TRIM(MID(SUBSTITUTE(K3,";",REPT(" ",99)),397,99)))+1,999))-1),_Lookup!$A:$B,2,FALSE),"?")&"×"&LEFT(MID(MID(TRIM(MID(SUBSTITUTE(K3,";",REPT(" ",99)),397,99)),FIND(":",TRIM(MID(SUBSTITUTE(K3,";",REPT(" ",99)),397,99)))+1,999),FIND(":",MID(TRIM(MID(SUBSTITUTE(K3,";",REPT(" ",99)),397,99)),FIND(":",TRIM(MID(SUBSTITUTE(K3,";",REPT(" ",99)),397,99)))+1,999))+1,999),FIND(":",MID(MID(TRIM(MID(SUBSTITUTE(K3,";",REPT(" ",99)),397,99)),FIND(":",TRIM(MID(SUBSTITUTE(K3,";",REPT(" ",99)),397,99)))+1,999),FIND(":",MID(TRIM(MID(SUBSTITUTE(K3,";",REPT(" ",99)),397,99)),FIND(":",TRIM(MID(SUBSTITUTE(K3,";",REPT(" ",99)),397,99)))+1,999))+1,999))-1))))
A4: 500002 | B4: 대왕 고등어(보스) | C4: 100001 | D4: =IFERROR(VLOOKUP(C4,ItemData_Fish!$A:$B,2,FALSE),"") | E4: 1000 | F4: 20 | G4: 60 | H4: 120 | I4: 72;84;96;108 | J4: TRUE | K4: ItemData_Materials:300001:5:0.5;ItemData_Equipment:200001:1:0.1 | L4: =IF(K4="","",TEXTJOIN("; ",TRUE,IF(TRIM(MID(SUBSTITUTE(K4,";",REPT(" ",99)),1,99))="","",IFERROR(VLOOKUP(--LEFT(MID(TRIM(MID(SUBSTITUTE(K4,";",REPT(" ",99)),1,99)),FIND(":",TRIM(MID(SUBSTITUTE(K4,";",REPT(" ",99)),1,99)))+1,999),FIND(":",MID(TRIM(MID(SUBSTITUTE(K4,";",REPT(" ",99)),1,99)),FIND(":",TRIM(MID(SUBSTITUTE(K4,";",REPT(" ",99)),1,99)))+1,999))-1),_Lookup!$A:$B,2,FALSE),"?")&"×"&LEFT(MID(MID(TRIM(MID(SUBSTITUTE(K4,";",REPT(" ",99)),1,99)),FIND(":",TRIM(MID(SUBSTITUTE(K4,";",REPT(" ",99)),1,99)))+1,999),FIND(":",MID(TRIM(MID(SUBSTITUTE(K4,";",REPT(" ",99)),1,99)),FIND(":",TRIM(MID(SUBSTITUTE(K4,";",REPT(" ",99)),1,99)))+1,999))+1,999),FIND(":",MID(MID(TRIM(MID(SUBSTITUTE(K4,";",REPT(" ",99)),1,99)),FIND(":",TRIM(MID(SUBSTITUTE(K4,";",REPT(" ",99)),1,99)))+1,999),FIND(":",MID(TRIM(MID(SUBSTITUTE(K4,";",REPT(" ",99)),1,99)),FIND(":",TRIM(MID(SUBSTITUTE(K4,";",REPT(" ",99)),1,99)))+1,999))+1,999))-1)),IF(TRIM(MID(SUBSTITUTE(K4,";",REPT(" ",99)),100,99))="","",IFERROR(VLOOKUP(--LEFT(MID(TRIM(MID(SUBSTITUTE(K4,";",REPT(" ",99)),100,99)),FIND(":",TRIM(MID(SUBSTITUTE(K4,";",REPT(" ",99)),100,99)))+1,999),FIND(":",MID(TRIM(MID(SUBSTITUTE(K4,";",REPT(" ",99)),100,99)),FIND(":",TRIM(MID(SUBSTITUTE(K4,";",REPT(" ",99)),100,99)))+1,999))-1),_Lookup!$A:$B,2,FALSE),"?")&"×"&LEFT(MID(MID(TRIM(MID(SUBSTITUTE(K4,";",REPT(" ",99)),100,99)),FIND(":",TRIM(MID(SUBSTITUTE(K4,";",REPT(" ",99)),100,99)))+1,999),FIND(":",MID(TRIM(MID(SUBSTITUTE(K4,";",REPT(" ",99)),100,99)),FIND(":",TRIM(MID(SUBSTITUTE(K4,";",REPT(" ",99)),100,99)))+1,999))+1,999),FIND(":",MID(MID(TRIM(MID(SUBSTITUTE(K4,";",REPT(" ",99)),100,99)),FIND(":",TRIM(MID(SUBSTITUTE(K4,";",REPT(" ",99)),100,99)))+1,999),FIND(":",MID(TRIM(MID(SUBSTITUTE(K4,";",REPT(" ",99)),100,99)),FIND(":",TRIM(MID(SUBSTITUTE(K4,";",REPT(" ",99)),100,99)))+1,999))+1,999))-1)),IF(TRIM(MID(SUBSTITUTE(K4,";",REPT(" ",99)),199,99))="","",IFERROR(VLOOKUP(--LEFT(MID(TRIM(MID(SUBSTITUTE(K4,";",REPT(" ",99)),199,99)),FIND(":",TRIM(MID(SUBSTITUTE(K4,";",REPT(" ",99)),199,99)))+1,999),FIND(":",MID(TRIM(MID(SUBSTITUTE(K4,";",REPT(" ",99)),199,99)),FIND(":",TRIM(MID(SUBSTITUTE(K4,";",REPT(" ",99)),199,99)))+1,999))-1),_Lookup!$A:$B,2,FALSE),"?")&"×"&LEFT(MID(MID(TRIM(MID(SUBSTITUTE(K4,";",REPT(" ",99)),199,99)),FIND(":",TRIM(MID(SUBSTITUTE(K4,";",REPT(" ",99)),199,99)))+1,999),FIND(":",MID(TRIM(MID(SUBSTITUTE(K4,";",REPT(" ",99)),199,99)),FIND(":",TRIM(MID(SUBSTITUTE(K4,";",REPT(" ",99)),199,99)))+1,999))+1,999),FIND(":",MID(MID(TRIM(MID(SUBSTITUTE(K4,";",REPT(" ",99)),199,99)),FIND(":",TRIM(MID(SUBSTITUTE(K4,";",REPT(" ",99)),199,99)))+1,999),FIND(":",MID(TRIM(MID(SUBSTITUTE(K4,";",REPT(" ",99)),199,99)),FIND(":",TRIM(MID(SUBSTITUTE(K4,";",REPT(" ",99)),199,99)))+1,999))+1,999))-1)),IF(TRIM(MID(SUBSTITUTE(K4,";",REPT(" ",99)),298,99))="","",IFERROR(VLOOKUP(--LEFT(MID(TRIM(MID(SUBSTITUTE(K4,";",REPT(" ",99)),298,99)),FIND(":",TRIM(MID(SUBSTITUTE(K4,";",REPT(" ",99)),298,99)))+1,999),FIND(":",MID(TRIM(MID(SUBSTITUTE(K4,";",REPT(" ",99)),298,99)),FIND(":",TRIM(MID(SUBSTITUTE(K4,";",REPT(" ",99)),298,99)))+1,999))-1),_Lookup!$A:$B,2,FALSE),"?")&"×"&LEFT(MID(MID(TRIM(MID(SUBSTITUTE(K4,";",REPT(" ",99)),298,99)),FIND(":",TRIM(MID(SUBSTITUTE(K4,";",REPT(" ",99)),298,99)))+1,999),FIND(":",MID(TRIM(MID(SUBSTITUTE(K4,";",REPT(" ",99)),298,99)),FIND(":",TRIM(MID(SUBSTITUTE(K4,";",REPT(" ",99)),298,99)))+1,999))+1,999),FIND(":",MID(MID(TRIM(MID(SUBSTITUTE(K4,";",REPT(" ",99)),298,99)),FIND(":",TRIM(MID(SUBSTITUTE(K4,";",REPT(" ",99)),298,99)))+1,999),FIND(":",MID(TRIM(MID(SUBSTITUTE(K4,";",REPT(" ",99)),298,99)),FIND(":",TRIM(MID(SUBSTITUTE(K4,";",REPT(" ",99)),298,99)))+1,999))+1,999))-1)),IF(TRIM(MID(SUBSTITUTE(K4,";",REPT(" ",99)),397,99))="","",IFERROR(VLOOKUP(--LEFT(MID(TRIM(MID(SUBSTITUTE(K4,";",REPT(" ",99)),397,99)),FIND(":",TRIM(MID(SUBSTITUTE(K4,";",REPT(" ",99)),397,99)))+1,999),FIND(":",MID(TRIM(MID(SUBSTITUTE(K4,";",REPT(" ",99)),397,99)),FIND(":",TRIM(MID(SUBSTITUTE(K4,";",REPT(" ",99)),397,99)))+1,999))-1),_Lookup!$A:$B,2,FALSE),"?")&"×"&LEFT(MID(MID(TRIM(MID(SUBSTITUTE(K4,";",REPT(" ",99)),397,99)),FIND(":",TRIM(MID(SUBSTITUTE(K4,";",REPT(" ",99)),397,99)))+1,999),FIND(":",MID(TRIM(MID(SUBSTITUTE(K4,";",REPT(" ",99)),397,99)),FIND(":",TRIM(MID(SUBSTITUTE(K4,";",REPT(" ",99)),397,99)))+1,999))+1,999),FIND(":",MID(MID(TRIM(MID(SUBSTITUTE(K4,";",REPT(" ",99)),397,99)),FIND(":",TRIM(MID(SUBSTITUTE(K4,";",REPT(" ",99)),397,99)))+1,999),FIND(":",MID(TRIM(MID(SUBSTITUTE(K4,";",REPT(" ",99)),397,99)),FIND(":",TRIM(MID(SUBSTITUTE(K4,";",REPT(" ",99)),397,99)))+1,999))+1,999))-1))))
D5: =IFERROR(VLOOKUP(C5,ItemData_Fish!$A:$B,2,FALSE),"") | L5: =IF(K5="","",TEXTJOIN("; ",TRUE,IF(TRIM(MID(SUBSTITUTE(K5,";",REPT(" ",99)),1,99))="","",IFERROR(VLOOKUP(--LEFT(MID(TRIM(MID(SUBSTITUTE(K5,";",REPT(" ",99)),1,99)),FIND(":",TRIM(MID(SUBSTITUTE(K5,";",REPT(" ",99)),1,99)))+1,999),FIND(":",MID(TRIM(MID(SUBSTITUTE(K5,";",REPT(" ",99)),1,99)),FIND(":",TRIM(MID(SUBSTITUTE(K5,";",REPT(" ",99)),1,99)))+1,999))-1),_Lookup!$A:$B,2,FALSE),"?")&"×"&LEFT(MID(MID(TRIM(MID(SUBSTITUTE(K5,";",REPT(" ",99)),1,99)),FIND(":",TRIM(MID(SUBSTITUTE(K5,";",REPT(" ",99)),1,99)))+1,999),FIND(":",MID(TRIM(MID(SUBSTITUTE(K5,";",REPT(" ",99)),1,99)),FIND(":",TRIM(MID(SUBSTITUTE(K5,";",REPT(" ",99)),1,99)))+1,999))+1,999),FIND(":",MID(MID(TRIM(MID(SUBSTITUTE(K5,";",REPT(" ",99)),1,99)),FIND(":",TRIM(MID(SUBSTITUTE(K5,";",REPT(" ",99)),1,99)))+1,999),FIND(":",MID(TRIM(MID(SUBSTITUTE(K5,";",REPT(" ",99)),1,99)),FIND(":",TRIM(MID(SUBSTITUTE(K5,";",REPT(" ",99)),1,99)))+1,999))+1,999))-1)),IF(TRIM(MID(SUBSTITUTE(K5,";",REPT(" ",99)),100,99))="","",IFERROR(VLOOKUP(--LEFT(MID(TRIM(MID(SUBSTITUTE(K5,";",REPT(" ",99)),100,99)),FIND(":",TRIM(MID(SUBSTITUTE(K5,";",REPT(" ",99)),100,99)))+1,999),FIND(":",MID(TRIM(MID(SUBSTITUTE(K5,";",REPT(" ",99)),100,99)),FIND(":",TRIM(MID(SUBSTITUTE(K5,";",REPT(" ",99)),100,99)))+1,999))-1),_Lookup!$A:$B,2,FALSE),"?")&"×"&LEFT(MID(MID(TRIM(MID(SUBSTITUTE(K5,";",REPT(" ",99)),100,99)),FIND(":",TRIM(MID(SUBSTITUTE(K5,";",REPT(" ",99)),100,99)))+1,999),FIND(":",MID(TRIM(MID(SUBSTITUTE(K5,";",REPT(" ",99)),100,99)),FIND(":",TRIM(MID(SUBSTITUTE(K5,";",REPT(" ",99)),100,99)))+1,999))+1,999),FIND(":",MID(MID(TRIM(MID(SUBSTITUTE(K5,";",REPT(" ",99)),100,99)),FIND(":",TRIM(MID(SUBSTITUTE(K5,";",REPT(" ",99)),100,99)))+1,999),FIND(":",MID(TRIM(MID(SUBSTITUTE(K5,";",REPT(" ",99)),100,99)),FIND(":",TRIM(MID(SUBSTITUTE(K5,";",REPT(" ",99)),100,99)))+1,999))+1,999))-1)),IF(TRIM(MID(SUBSTITUTE(K5,";",REPT(" ",99)),199,99))="","",IFERROR(VLOOKUP(--LEFT(MID(TRIM(MID(SUBSTITUTE(K5,";",REPT(" ",99)),199,99)),FIND(":",TRIM(MID(SUBSTITUTE(K5,";",REPT(" ",99)),199,99)))+1,999),FIND(":",MID(TRIM(MID(SUBSTITUTE(K5,";",REPT(" ",99)),199,99)),FIND(":",TRIM(MID(SUBSTITUTE(K5,";",REPT(" ",99)),199,99)))+1,999))-1),_Lookup!$A:$B,2,FALSE),"?")&"×"&LEFT(MID(MID(TRIM(MID(SUBSTITUTE(K5,";",REPT(" ",99)),199,99)),FIND(":",TRIM(MID(SUBSTITUTE(K5,";",REPT(" ",99)),199,99)))+1,999),FIND(":",MID(TRIM(MID(SUBSTITUTE(K5,";",REPT(" ",99)),199,99)),FIND(":",TRIM(MID(SUBSTITUTE(K5,";",REPT(" ",99)),199,99)))+1,999))+1,999),FIND(":",MID(MID(TRIM(MID(SUBSTITUTE(K5,";",REPT(" ",99)),199,99)),FIND(":",TRIM(MID(SUBSTITUTE(K5,";",REPT(" ",99)),199,99)))+1,999),FIND(":",MID(TRIM(MID(SUBSTITUTE(K5,";",REPT(" ",99)),199,99)),FIND(":",TRIM(MID(SUBSTITUTE(K5,";",REPT(" ",99)),199,99)))+1,999))+1,999))-1)),IF(TRIM(MID(SUBSTITUTE(K5,";",REPT(" ",99)),298,99))="","",IFERROR(VLOOKUP(--LEFT(MID(TRIM(MID(SUBSTITUTE(K5,";",REPT(" ",99)),298,99)),FIND(":",TRIM(MID(SUBSTITUTE(K5,";",REPT(" ",99)),298,99)))+1,999),FIND(":",MID(TRIM(MID(SUBSTITUTE(K5,";",REPT(" ",99)),298,99)),FIND(":",TRIM(MID(SUBSTITUTE(K5,";",REPT(" ",99)),298,99)))+1,999))-1),_Lookup!$A:$B,2,FALSE),"?")&"×"&LEFT(MID(MID(TRIM(MID(SUBSTITUTE(K5,";",REPT(" ",99)),298,99)),FIND(":",TRIM(MID(SUBSTITUTE(K5,";",REPT(" ",99)),298,99)))+1,999),FIND(":",MID(TRIM(MID(SUBSTITUTE(K5,";",REPT(" ",99)),298,99)),FIND(":",TRIM(MID(SUBSTITUTE(K5,";",REPT(" ",99)),298,99)))+1,999))+1,999),FIND(":",MID(MID(TRIM(MID(SUBSTITUTE(K5,";",REPT(" ",99)),298,99)),FIND(":",TRIM(MID(SUBSTITUTE(K5,";",REPT(" ",99)),298,99)))+1,999),FIND(":",MID(TRIM(MID(SUBSTITUTE(K5,";",REPT(" ",99)),298,99)),FIND(":",TRIM(MID(SUBSTITUTE(K5,";",REPT(" ",99)),298,99)))+1,999))+1,999))-1)),IF(TRIM(MID(SUBSTITUTE(K5,";",REPT(" ",99)),397,99))="","",IFERROR(VLOOKUP(--LEFT(MID(TRIM(MID(SUBSTITUTE(K5,";",REPT(" ",99)),397,99)),FIND(":",TRIM(MID(SUBSTITUTE(K5,";",REPT(" ",99)),397,99)))+1,999),FIND(":",MID(TRIM(MID(SUBSTITUTE(K5,";",REPT(" ",99)),397,99)),FIND(":",TRIM(MID(SUBSTITUTE(K5,";",REPT(" ",99)),397,99)))+1,999))-1),_Lookup!$A:$B,2,FALSE),"?")&"×"&LEFT(MID(MID(TRIM(MID(SUBSTITUTE(K5,";",REPT(" ",99)),397,99)),FIND(":",TRIM(MID(SUBSTITUTE(K5,";",REPT(" ",99)),397,99)))+1,999),FIND(":",MID(TRIM(MID(SUBSTITUTE(K5,";",REPT(" ",99)),397,99)),FIND(":",TRIM(MID(SUBSTITUTE(K5,";",REPT(" ",99)),397,99)))+1,999))+1,999),FIND(":",MID(MID(TRIM(MID(SUBSTITUTE(K5,";",REPT(" ",99)),397,99)),FIND(":",TRIM(MID(SUBSTITUTE(K5,";",REPT(" ",99)),397,99)))+1,999),FIND(":",MID(TRIM(MID(SUBSTITUTE(K5,";",REPT(" ",99)),397,99)),FIND(":",TRIM(MID(SUBSTITUTE(K5,";",REPT(" ",99)),397,99)))+1,999))+1,999))-1))))
D6: =IFERROR(VLOOKUP(C6,ItemData_Fish!$A:$B,2,FALSE),"") | L6: =IF(K6="","",TEXTJOIN("; ",TRUE,IF(TRIM(MID(SUBSTITUTE(K6,";",REPT(" ",99)),1,99))="","",IFERROR(VLOOKUP(--LEFT(MID(TRIM(MID(SUBSTITUTE(K6,";",REPT(" ",99)),1,99)),FIND(":",TRIM(MID(SUBSTITUTE(K6,";",REPT(" ",99)),1,99)))+1,999),FIND(":",MID(TRIM(MID(SUBSTITUTE(K6,";",REPT(" ",99)),1,99)),FIND(":",TRIM(MID(SUBSTITUTE(K6,";",REPT(" ",99)),1,99)))+1,999))-1),_Lookup!$A:$B,2,FALSE),"?")&"×"&LEFT(MID(MID(TRIM(MID(SUBSTITUTE(K6,";",REPT(" ",99)),1,99)),FIND(":",TRIM(MID(SUBSTITUTE(K6,";",REPT(" ",99)),1,99)))+1,999),FIND(":",MID(TRIM(MID(SUBSTITUTE(K6,";",REPT(" ",99)),1,99)),FIND(":",TRIM(MID(SUBSTITUTE(K6,";",REPT(" ",99)),1,99)))+1,999))+1,999),FIND(":",MID(MID(TRIM(MID(SUBSTITUTE(K6,";",REPT(" ",99)),1,99)),FIND(":",TRIM(MID(SUBSTITUTE(K6,";",REPT(" ",99)),1,99)))+1,999),FIND(":",MID(TRIM(MID(SUBSTITUTE(K6,";",REPT(" ",99)),1,99)),FIND(":",TRIM(MID(SUBSTITUTE(K6,";",REPT(" ",99)),1,99)))+1,999))+1,999))-1)),IF(TRIM(MID(SUBSTITUTE(K6,";",REPT(" ",99)),100,99))="","",IFERROR(VLOOKUP(--LEFT(MID(TRIM(MID(SUBSTITUTE(K6,";",REPT(" ",99)),100,99)),FIND(":",TRIM(MID(SUBSTITUTE(K6,";",REPT(" ",99)),100,99)))+1,999),FIND(":",MID(TRIM(MID(SUBSTITUTE(K6,";",REPT(" ",99)),100,99)),FIND(":",TRIM(MID(SUBSTITUTE(K6,";",REPT(" ",99)),100,99)))+1,999))-1),_Lookup!$A:$B,2,FALSE),"?")&"×"&LEFT(MID(MID(TRIM(MID(SUBSTITUTE(K6,";",REPT(" ",99)),100,99)),FIND(":",TRIM(MID(SUBSTITUTE(K6,";",REPT(" ",99)),100,99)))+1,999),FIND(":",MID(TRIM(MID(SUBSTITUTE(K6,";",REPT(" ",99)),100,99)),FIND(":",TRIM(MID(SUBSTITUTE(K6,";",REPT(" ",99)),100,99)))+1,999))+1,999),FIND(":",MID(MID(TRIM(MID(SUBSTITUTE(K6,";",REPT(" ",99)),100,99)),FIND(":",TRIM(MID(SUBSTITUTE(K6,";",REPT(" ",99)),100,99)))+1,999),FIND(":",MID(TRIM(MID(SUBSTITUTE(K6,";",REPT(" ",99)),100,99)),FIND(":",TRIM(MID(SUBSTITUTE(K6,";",REPT(" ",99)),100,99)))+1,999))+1,999))-1)),IF(TRIM(MID(SUBSTITUTE(K6,";",REPT(" ",99)),199,99))="","",IFERROR(VLOOKUP(--LEFT(MID(TRIM(MID(SUBSTITUTE(K6,";",REPT(" ",99)),199,99)),FIND(":",TRIM(MID(SUBSTITUTE(K6,";",REPT(" ",99)),199,99)))+1,999),FIND(":",MID(TRIM(MID(SUBSTITUTE(K6,";",REPT(" ",99)),199,99)),FIND(":",TRIM(MID(SUBSTITUTE(K6,";",REPT(" ",99)),199,99)))+1,999))-1),_Lookup!$A:$B,2,FALSE),"?")&"×"&LEFT(MID(MID(TRIM(MID(SUBSTITUTE(K6,";",REPT(" ",99)),199,99)),FIND(":",TRIM(MID(SUBSTITUTE(K6,";",REPT(" ",99)),199,99)))+1,999),FIND(":",MID(TRIM(MID(SUBSTITUTE(K6,";",REPT(" ",99)),199,99)),FIND(":",TRIM(MID(SUBSTITUTE(K6,";",REPT(" ",99)),199,99)))+1,999))+1,999),FIND(":",MID(MID(TRIM(MID(SUBSTITUTE(K6,";",REPT(" ",99)),199,99)),FIND(":",TRIM(MID(SUBSTITUTE(K6,";",REPT(" ",99)),199,99)))+1,999),FIND(":",MID(TRIM(MID(SUBSTITUTE(K6,";",REPT(" ",99)),199,99)),FIND(":",TRIM(MID(SUBSTITUTE(K6,";",REPT(" ",99)),199,99)))+1,999))+1,999))-1)),IF(TRIM(MID(SUBSTITUTE(K6,";",REPT(" ",99)),298,99))="","",IFERROR(VLOOKUP(--LEFT(MID(TRIM(MID(SUBSTITUTE(K6,";",REPT(" ",99)),298,99)),FIND(":",TRIM(MID(SUBSTITUTE(K6,";",REPT(" ",99)),298,99)))+1,999),FIND(":",MID(TRIM(MID(SUBSTITUTE(K6,";",REPT(" ",99)),298,99)),FIND(":",TRIM(MID(SUBSTITUTE(K6,";",REPT(" ",99)),298,99)))+1,999))-1),_Lookup!$A:$B,2,FALSE),"?")&"×"&LEFT(MID(MID(TRIM(MID(SUBSTITUTE(K6,";",REPT(" ",99)),298,99)),FIND(":",TRIM(MID(SUBSTITUTE(K6,";",REPT(" ",99)),298,99)))+1,999),FIND(":",MID(TRIM(MID(SUBSTITUTE(K6,";",REPT(" ",99)),298,99)),FIND(":",TRIM(MID(SUBSTITUTE(K6,";",REPT(" ",99)),298,99)))+1,999))+1,999),FIND(":",MID(MID(TRIM(MID(SUBSTITUTE(K6,";",REPT(" ",99)),298,99)),FIND(":",TRIM(MID(SUBSTITUTE(K6,";",REPT(" ",99)),298,99)))+1,999),FIND(":",MID(TRIM(MID(SUBSTITUTE(K6,";",REPT(" ",99)),298,99)),FIND(":",TRIM(MID(SUBSTITUTE(K6,";",REPT(" ",99)),298,99)))+1,999))+1,999))-1)),IF(TRIM(MID(SUBSTITUTE(K6,";",REPT(" ",99)),397,99))="","",IFERROR(VLOOKUP(--LEFT(MID(TRIM(MID(SUBSTITUTE(K6,";",REPT(" ",99)),397,99)),FIND(":",TRIM(MID(SUBSTITUTE(K6,";",REPT(" ",99)),397,99)))+1,999),FIND(":",MID(TRIM(MID(SUBSTITUTE(K6,";",REPT(" ",99)),397,99)),FIND(":",TRIM(MID(SUBSTITUTE(K6,";",REPT(" ",99)),397,99)))+1,999))-1),_Lookup!$A:$B,2,FALSE),"?")&"×"&LEFT(MID(MID(TRIM(MID(SUBSTITUTE(K6,";",REPT(" ",99)),397,99)),FIND(":",TRIM(MID(SUBSTITUTE(K6,";",REPT(" ",99)),397,99)))+1,999),FIND(":",MID(TRIM(MID(SUBSTITUTE(K6,";",REPT(" ",99)),397,99)),FIND(":",TRIM(MID(SUBSTITUTE(K6,";",REPT(" ",99)),397,99)))+1,999))+1,999),FIND(":",MID(MID(TRIM(MID(SUBSTITUTE(K6,";",REPT(" ",99)),397,99)),FIND(":",TRIM(MID(SUBSTITUTE(K6,";",REPT(" ",99)),397,99)))+1,999),FIND(":",MID(TRIM(MID(SUBSTITUTE(K6,";",REPT(" ",99)),397,99)),FIND(":",TRIM(MID(SUBSTITUTE(K6,";",REPT(" ",99)),397,99)))+1,999))+1,999))-1))))
